[2024-01-24T15:45:00.536-0300] {taskinstance.py:1159} INFO - Dependencies all met for dep_context=non-requeueable deps ti=<TaskInstance: cities_coleta_parquet.cwb scheduled__2024-01-24T18:43:51.769396+00:00 [queued]>
[2024-01-24T15:45:00.539-0300] {taskinstance.py:1159} INFO - Dependencies all met for dep_context=requeueable deps ti=<TaskInstance: cities_coleta_parquet.cwb scheduled__2024-01-24T18:43:51.769396+00:00 [queued]>
[2024-01-24T15:45:00.539-0300] {taskinstance.py:1361} INFO - Starting attempt 1 of 1
[2024-01-24T15:45:00.545-0300] {taskinstance.py:1382} INFO - Executing <Task(PythonOperator): cwb> on 2024-01-24 18:43:51.769396+00:00
[2024-01-24T15:45:00.549-0300] {standard_task_runner.py:57} INFO - Started process 21393 to run task
[2024-01-24T15:45:00.551-0300] {standard_task_runner.py:84} INFO - Running: ['airflow', 'tasks', 'run', 'cities_coleta_parquet', 'cwb', 'scheduled__2024-01-24T18:43:51.769396+00:00', '--job-id', '4909', '--raw', '--subdir', 'DAGS_FOLDER/dag.py', '--cfg-path', '/tmp/tmp_d324x1u']
[2024-01-24T15:45:00.551-0300] {standard_task_runner.py:85} INFO - Job 4909: Subtask cwb
[2024-01-24T15:45:00.571-0300] {task_command.py:416} INFO - Running <TaskInstance: cities_coleta_parquet.cwb scheduled__2024-01-24T18:43:51.769396+00:00 [running]> on host desktop
[2024-01-24T15:45:00.597-0300] {taskinstance.py:1662} INFO - Exporting env vars: AIRFLOW_CTX_DAG_EMAIL='datasetpibic@gmail.com' AIRFLOW_CTX_DAG_OWNER='airflow' AIRFLOW_CTX_DAG_ID='cities_coleta_parquet' AIRFLOW_CTX_TASK_ID='cwb' AIRFLOW_CTX_EXECUTION_DATE='2024-01-24T18:43:51.769396+00:00' AIRFLOW_CTX_TRY_NUMBER='1' AIRFLOW_CTX_DAG_RUN_ID='scheduled__2024-01-24T18:43:51.769396+00:00'
[2024-01-24T15:47:50.349-0300] {process_utils.py:131} INFO - Sending 15 to group 21393. PIDs of all processes in the group: [21393]
[2024-01-24T15:47:50.349-0300] {process_utils.py:86} INFO - Sending the signal 15 to group 21393
[2024-01-24T15:47:50.349-0300] {taskinstance.py:1632} ERROR - Received SIGTERM. Terminating subprocesses.
[2024-01-24T15:47:50.350-0300] {logging_mixin.py:154} INFO - curitiba - Error: Task received SIGTERM signal
[2024-01-24T15:47:50.350-0300] {taskinstance.py:1937} ERROR - Task failed with exception
Traceback (most recent call last):
  File "/home/felipe/airflow/dags/cities/curitiba.py", line 49, in curitiba
    response = req()
               ^^^^^
  File "/home/felipe/airflow/dags/cities/curitiba.py", line 6, in req
    response = requests.get(API_URL).json()
               ^^^^^^^^^^^^^^^^^^^^^
  File "/home/felipe/.local/lib/python3.11/site-packages/requests/api.py", line 73, in get
    return request("get", url, params=params, **kwargs)
           ^^^^^^^^^^^^^^^^^^^^^^^^^^^^^^^^^^^^^^^^^^^^
  File "/home/felipe/.local/lib/python3.11/site-packages/requests/api.py", line 59, in request
    return session.request(method=method, url=url, **kwargs)
           ^^^^^^^^^^^^^^^^^^^^^^^^^^^^^^^^^^^^^^^^^^^^^^^^^
  File "/home/felipe/.local/lib/python3.11/site-packages/requests/sessions.py", line 589, in request
    resp = self.send(prep, **send_kwargs)
           ^^^^^^^^^^^^^^^^^^^^^^^^^^^^^^
  File "/home/felipe/.local/lib/python3.11/site-packages/requests/sessions.py", line 703, in send
    r = adapter.send(request, **kwargs)
        ^^^^^^^^^^^^^^^^^^^^^^^^^^^^^^^
  File "/home/felipe/.local/lib/python3.11/site-packages/requests/adapters.py", line 486, in send
    resp = conn.urlopen(
           ^^^^^^^^^^^^^
  File "/home/felipe/.local/lib/python3.11/site-packages/urllib3/connectionpool.py", line 715, in urlopen
    httplib_response = self._make_request(
                       ^^^^^^^^^^^^^^^^^^^
  File "/home/felipe/.local/lib/python3.11/site-packages/urllib3/connectionpool.py", line 404, in _make_request
    self._validate_conn(conn)
  File "/home/felipe/.local/lib/python3.11/site-packages/urllib3/connectionpool.py", line 1058, in _validate_conn
    conn.connect()
  File "/home/felipe/.local/lib/python3.11/site-packages/urllib3/connection.py", line 419, in connect
    self.sock = ssl_wrap_socket(
                ^^^^^^^^^^^^^^^^
  File "/home/felipe/.local/lib/python3.11/site-packages/urllib3/util/ssl_.py", line 449, in ssl_wrap_socket
    ssl_sock = _ssl_wrap_socket_impl(
               ^^^^^^^^^^^^^^^^^^^^^^
  File "/home/felipe/.local/lib/python3.11/site-packages/urllib3/util/ssl_.py", line 493, in _ssl_wrap_socket_impl
    return ssl_context.wrap_socket(sock, server_hostname=server_hostname)
           ^^^^^^^^^^^^^^^^^^^^^^^^^^^^^^^^^^^^^^^^^^^^^^^^^^^^^^^^^^^^^^
  File "/usr/lib/python3.11/ssl.py", line 517, in wrap_socket
    return self.sslsocket_class._create(
           ^^^^^^^^^^^^^^^^^^^^^^^^^^^^^
  File "/usr/lib/python3.11/ssl.py", line 1104, in _create
    self.do_handshake()
  File "/usr/lib/python3.11/ssl.py", line 1375, in do_handshake
    self._sslobj.do_handshake()
  File "/home/felipe/.local/lib/python3.11/site-packages/airflow/models/taskinstance.py", line 1634, in signal_handler
    raise AirflowException("Task received SIGTERM signal")
airflow.exceptions.AirflowException: Task received SIGTERM signal

During handling of the above exception, another exception occurred:

Traceback (most recent call last):
  File "/home/felipe/.local/lib/python3.11/site-packages/airflow/operators/python.py", line 192, in execute
    return_value = self.execute_callable()
                   ^^^^^^^^^^^^^^^^^^^^^^^
  File "/home/felipe/.local/lib/python3.11/site-packages/airflow/operators/python.py", line 209, in execute_callable
    return self.python_callable(*self.op_args, **self.op_kwargs)
           ^^^^^^^^^^^^^^^^^^^^^^^^^^^^^^^^^^^^^^^^^^^^^^^^^^^^^
  File "/home/felipe/airflow/dags/cities/curitiba.py", line 54, in curitiba
    raise ValueError('Erro em Cwb!')
ValueError: Erro em Cwb!
[2024-01-24T15:47:50.453-0300] {taskinstance.py:1400} INFO - Marking task as FAILED. dag_id=cities_coleta_parquet, task_id=cwb, execution_date=20240124T184351, start_date=20240124T184500, end_date=20240124T184750
[2024-01-24T15:47:50.464-0300] {logging_mixin.py:154} WARNING - /home/felipe/.local/lib/python3.11/site-packages/airflow/utils/email.py:154 RemovedInAirflow3Warning: Fetching SMTP credentials from configuration variables will be deprecated in a future release. Please set credentials using a connection instead.
[2024-01-24T15:47:50.464-0300] {configuration.py:1050} WARNING - section/key [smtp/smtp_user] not found in config
[2024-01-24T15:47:50.465-0300] {email.py:270} INFO - Email alerting: attempt 1
[2024-01-24T15:47:50.466-0300] {configuration.py:1050} WARNING - section/key [smtp/smtp_user] not found in config
[2024-01-24T15:47:50.466-0300] {email.py:270} INFO - Email alerting: attempt 1
[2024-01-24T15:47:50.467-0300] {taskinstance.py:2007} ERROR - Failed to send email to: ['datasetpibic@gmail.com']
Traceback (most recent call last):
  File "/home/felipe/airflow/dags/cities/curitiba.py", line 49, in curitiba
    response = req()
               ^^^^^
  File "/home/felipe/airflow/dags/cities/curitiba.py", line 6, in req
    response = requests.get(API_URL).json()
               ^^^^^^^^^^^^^^^^^^^^^
  File "/home/felipe/.local/lib/python3.11/site-packages/requests/api.py", line 73, in get
    return request("get", url, params=params, **kwargs)
           ^^^^^^^^^^^^^^^^^^^^^^^^^^^^^^^^^^^^^^^^^^^^
  File "/home/felipe/.local/lib/python3.11/site-packages/requests/api.py", line 59, in request
    return session.request(method=method, url=url, **kwargs)
           ^^^^^^^^^^^^^^^^^^^^^^^^^^^^^^^^^^^^^^^^^^^^^^^^^
  File "/home/felipe/.local/lib/python3.11/site-packages/requests/sessions.py", line 589, in request
    resp = self.send(prep, **send_kwargs)
           ^^^^^^^^^^^^^^^^^^^^^^^^^^^^^^
  File "/home/felipe/.local/lib/python3.11/site-packages/requests/sessions.py", line 703, in send
    r = adapter.send(request, **kwargs)
        ^^^^^^^^^^^^^^^^^^^^^^^^^^^^^^^
  File "/home/felipe/.local/lib/python3.11/site-packages/requests/adapters.py", line 486, in send
    resp = conn.urlopen(
           ^^^^^^^^^^^^^
  File "/home/felipe/.local/lib/python3.11/site-packages/urllib3/connectionpool.py", line 715, in urlopen
    httplib_response = self._make_request(
                       ^^^^^^^^^^^^^^^^^^^
  File "/home/felipe/.local/lib/python3.11/site-packages/urllib3/connectionpool.py", line 404, in _make_request
    self._validate_conn(conn)
  File "/home/felipe/.local/lib/python3.11/site-packages/urllib3/connectionpool.py", line 1058, in _validate_conn
    conn.connect()
  File "/home/felipe/.local/lib/python3.11/site-packages/urllib3/connection.py", line 419, in connect
    self.sock = ssl_wrap_socket(
                ^^^^^^^^^^^^^^^^
  File "/home/felipe/.local/lib/python3.11/site-packages/urllib3/util/ssl_.py", line 449, in ssl_wrap_socket
    ssl_sock = _ssl_wrap_socket_impl(
               ^^^^^^^^^^^^^^^^^^^^^^
  File "/home/felipe/.local/lib/python3.11/site-packages/urllib3/util/ssl_.py", line 493, in _ssl_wrap_socket_impl
    return ssl_context.wrap_socket(sock, server_hostname=server_hostname)
           ^^^^^^^^^^^^^^^^^^^^^^^^^^^^^^^^^^^^^^^^^^^^^^^^^^^^^^^^^^^^^^
  File "/usr/lib/python3.11/ssl.py", line 517, in wrap_socket
    return self.sslsocket_class._create(
           ^^^^^^^^^^^^^^^^^^^^^^^^^^^^^
  File "/usr/lib/python3.11/ssl.py", line 1104, in _create
    self.do_handshake()
  File "/usr/lib/python3.11/ssl.py", line 1375, in do_handshake
    self._sslobj.do_handshake()
  File "/home/felipe/.local/lib/python3.11/site-packages/airflow/models/taskinstance.py", line 1634, in signal_handler
    raise AirflowException("Task received SIGTERM signal")
airflow.exceptions.AirflowException: Task received SIGTERM signal

During handling of the above exception, another exception occurred:

Traceback (most recent call last):
  File "/home/felipe/.local/lib/python3.11/site-packages/airflow/models/taskinstance.py", line 1518, in _run_raw_task
    self._execute_task_with_callbacks(context, test_mode, session=session)
  File "/home/felipe/.local/lib/python3.11/site-packages/airflow/models/taskinstance.py", line 1681, in _execute_task_with_callbacks
    result = self._execute_task(context, task_orig)
             ^^^^^^^^^^^^^^^^^^^^^^^^^^^^^^^^^^^^^^
  File "/home/felipe/.local/lib/python3.11/site-packages/airflow/models/taskinstance.py", line 1744, in _execute_task
    result = execute_callable(context=context, **execute_callable_kwargs)
             ^^^^^^^^^^^^^^^^^^^^^^^^^^^^^^^^^^^^^^^^^^^^^^^^^^^^^^^^^^^^
  File "/home/felipe/.local/lib/python3.11/site-packages/airflow/operators/python.py", line 192, in execute
    return_value = self.execute_callable()
                   ^^^^^^^^^^^^^^^^^^^^^^^
  File "/home/felipe/.local/lib/python3.11/site-packages/airflow/operators/python.py", line 209, in execute_callable
    return self.python_callable(*self.op_args, **self.op_kwargs)
           ^^^^^^^^^^^^^^^^^^^^^^^^^^^^^^^^^^^^^^^^^^^^^^^^^^^^^
  File "/home/felipe/airflow/dags/cities/curitiba.py", line 54, in curitiba
    raise ValueError('Erro em Cwb!')
ValueError: Erro em Cwb!

During handling of the above exception, another exception occurred:

Traceback (most recent call last):
  File "/home/felipe/.local/lib/python3.11/site-packages/airflow/models/taskinstance.py", line 2420, in email_alert
    send_email(task.email, subject, html_content)
  File "/home/felipe/.local/lib/python3.11/site-packages/airflow/utils/email.py", line 80, in send_email
    return backend(
           ^^^^^^^^
  File "/home/felipe/.local/lib/python3.11/site-packages/airflow/utils/email.py", line 154, in send_email_smtp
    send_mime_email(e_from=mail_from, e_to=recipients, mime_msg=msg, conn_id=conn_id, dryrun=dryrun)
  File "/home/felipe/.local/lib/python3.11/site-packages/airflow/utils/email.py", line 272, in send_mime_email
    smtp_conn = _get_smtp_connection(smtp_host, smtp_port, smtp_timeout, smtp_ssl)
                ^^^^^^^^^^^^^^^^^^^^^^^^^^^^^^^^^^^^^^^^^^^^^^^^^^^^^^^^^^^^^^^^^^
  File "/home/felipe/.local/lib/python3.11/site-packages/airflow/utils/email.py", line 316, in _get_smtp_connection
    return smtplib.SMTP(host=host, port=port, timeout=timeout)
           ^^^^^^^^^^^^^^^^^^^^^^^^^^^^^^^^^^^^^^^^^^^^^^^^^^^
  File "/usr/lib/python3.11/smtplib.py", line 255, in __init__
    (code, msg) = self.connect(host, port)
                  ^^^^^^^^^^^^^^^^^^^^^^^^
  File "/usr/lib/python3.11/smtplib.py", line 341, in connect
    self.sock = self._get_socket(host, port, self.timeout)
                ^^^^^^^^^^^^^^^^^^^^^^^^^^^^^^^^^^^^^^^^^^
  File "/usr/lib/python3.11/smtplib.py", line 312, in _get_socket
    return socket.create_connection((host, port), timeout,
           ^^^^^^^^^^^^^^^^^^^^^^^^^^^^^^^^^^^^^^^^^^^^^^^
  File "/usr/lib/python3.11/socket.py", line 851, in create_connection
    raise exceptions[0]
  File "/usr/lib/python3.11/socket.py", line 836, in create_connection
    sock.connect(sa)
ConnectionRefusedError: [Errno 111] Connection refused

During handling of the above exception, another exception occurred:

Traceback (most recent call last):
  File "/home/felipe/.local/lib/python3.11/site-packages/airflow/models/taskinstance.py", line 2005, in handle_failure
    self.email_alert(error, task)
  File "/home/felipe/.local/lib/python3.11/site-packages/airflow/models/taskinstance.py", line 2422, in email_alert
    send_email(task.email, subject, html_content_err)
  File "/home/felipe/.local/lib/python3.11/site-packages/airflow/utils/email.py", line 80, in send_email
    return backend(
           ^^^^^^^^
  File "/home/felipe/.local/lib/python3.11/site-packages/airflow/utils/email.py", line 154, in send_email_smtp
    send_mime_email(e_from=mail_from, e_to=recipients, mime_msg=msg, conn_id=conn_id, dryrun=dryrun)
  File "/home/felipe/.local/lib/python3.11/site-packages/airflow/utils/email.py", line 272, in send_mime_email
    smtp_conn = _get_smtp_connection(smtp_host, smtp_port, smtp_timeout, smtp_ssl)
                ^^^^^^^^^^^^^^^^^^^^^^^^^^^^^^^^^^^^^^^^^^^^^^^^^^^^^^^^^^^^^^^^^^
  File "/home/felipe/.local/lib/python3.11/site-packages/airflow/utils/email.py", line 316, in _get_smtp_connection
    return smtplib.SMTP(host=host, port=port, timeout=timeout)
           ^^^^^^^^^^^^^^^^^^^^^^^^^^^^^^^^^^^^^^^^^^^^^^^^^^^
  File "/usr/lib/python3.11/smtplib.py", line 255, in __init__
    (code, msg) = self.connect(host, port)
                  ^^^^^^^^^^^^^^^^^^^^^^^^
  File "/usr/lib/python3.11/smtplib.py", line 341, in connect
    self.sock = self._get_socket(host, port, self.timeout)
                ^^^^^^^^^^^^^^^^^^^^^^^^^^^^^^^^^^^^^^^^^^
  File "/usr/lib/python3.11/smtplib.py", line 312, in _get_socket
    return socket.create_connection((host, port), timeout,
           ^^^^^^^^^^^^^^^^^^^^^^^^^^^^^^^^^^^^^^^^^^^^^^^
  File "/usr/lib/python3.11/socket.py", line 851, in create_connection
    raise exceptions[0]
  File "/usr/lib/python3.11/socket.py", line 836, in create_connection
    sock.connect(sa)
ConnectionRefusedError: [Errno 111] Connection refused
[2024-01-24T15:47:50.475-0300] {standard_task_runner.py:104} ERROR - Failed to execute job 4909 for task cwb (Erro em Cwb!; 21393)
[2024-01-24T15:47:50.521-0300] {process_utils.py:79} INFO - Process psutil.Process(pid=21393, status='terminated', exitcode=1, started='15:44:59') (21393) terminated with exit code 1
