[2024-01-19T21:49:30.564-0300] {taskinstance.py:1159} INFO - Dependencies all met for dep_context=non-requeueable deps ti=<TaskInstance: cities_coleta_parquet.saopaulo scheduled__2024-01-20T00:48:23.269866+00:00 [queued]>
[2024-01-19T21:49:30.567-0300] {taskinstance.py:1159} INFO - Dependencies all met for dep_context=requeueable deps ti=<TaskInstance: cities_coleta_parquet.saopaulo scheduled__2024-01-20T00:48:23.269866+00:00 [queued]>
[2024-01-19T21:49:30.567-0300] {taskinstance.py:1361} INFO - Starting attempt 1 of 1
[2024-01-19T21:49:30.584-0300] {taskinstance.py:1382} INFO - Executing <Task(PythonOperator): saopaulo> on 2024-01-20 00:48:23.269866+00:00
[2024-01-19T21:49:30.588-0300] {standard_task_runner.py:57} INFO - Started process 95562 to run task
[2024-01-19T21:49:30.590-0300] {standard_task_runner.py:84} INFO - Running: ['airflow', 'tasks', 'run', 'cities_coleta_parquet', 'saopaulo', 'scheduled__2024-01-20T00:48:23.269866+00:00', '--job-id', '4595', '--raw', '--subdir', 'DAGS_FOLDER/dag.py', '--cfg-path', '/tmp/tmpjrywrde5']
[2024-01-19T21:49:30.590-0300] {standard_task_runner.py:85} INFO - Job 4595: Subtask saopaulo
[2024-01-19T21:49:30.612-0300] {task_command.py:416} INFO - Running <TaskInstance: cities_coleta_parquet.saopaulo scheduled__2024-01-20T00:48:23.269866+00:00 [running]> on host desktop
[2024-01-19T21:49:30.647-0300] {taskinstance.py:1662} INFO - Exporting env vars: AIRFLOW_CTX_DAG_EMAIL='datasetpibic@gmail.com' AIRFLOW_CTX_DAG_OWNER='airflow' AIRFLOW_CTX_DAG_ID='cities_coleta_parquet' AIRFLOW_CTX_TASK_ID='saopaulo' AIRFLOW_CTX_EXECUTION_DATE='2024-01-20T00:48:23.269866+00:00' AIRFLOW_CTX_TRY_NUMBER='1' AIRFLOW_CTX_DAG_RUN_ID='scheduled__2024-01-20T00:48:23.269866+00:00'
[2024-01-19T21:49:30.796-0300] {logging_mixin.py:154} INFO - true
[2024-01-19T21:49:30.796-0300] {logging_mixin.py:154} INFO - <Response [200]>
[2024-01-19T21:49:30.989-0300] {logging_mixin.py:154} INFO - sao_paulo - Error: 'NoneType' object is not subscriptable
[2024-01-19T21:49:30.990-0300] {taskinstance.py:1937} ERROR - Task failed with exception
Traceback (most recent call last):
  File "/home/felipe/airflow/dags/cities/sao_paulo.py", line 39, in sao_paulo
    processed_response = process_response(response)
                         ^^^^^^^^^^^^^^^^^^^^^^^^^^
  File "/home/felipe/airflow/dags/cities/sao_paulo.py", line 23, in process_response
    for linha in response['l']:
                 ~~~~~~~~^^^^^
TypeError: 'NoneType' object is not subscriptable

During handling of the above exception, another exception occurred:

Traceback (most recent call last):
  File "/home/felipe/.local/lib/python3.11/site-packages/airflow/operators/python.py", line 192, in execute
    return_value = self.execute_callable()
                   ^^^^^^^^^^^^^^^^^^^^^^^
  File "/home/felipe/.local/lib/python3.11/site-packages/airflow/operators/python.py", line 209, in execute_callable
    return self.python_callable(*self.op_args, **self.op_kwargs)
           ^^^^^^^^^^^^^^^^^^^^^^^^^^^^^^^^^^^^^^^^^^^^^^^^^^^^^
  File "/home/felipe/airflow/dags/cities/sao_paulo.py", line 43, in sao_paulo
    raise ValueError('Erro em Sao Paulo!')
ValueError: Erro em Sao Paulo!
[2024-01-19T21:49:30.992-0300] {taskinstance.py:1400} INFO - Marking task as FAILED. dag_id=cities_coleta_parquet, task_id=saopaulo, execution_date=20240120T004823, start_date=20240120T004930, end_date=20240120T004930
[2024-01-19T21:49:31.004-0300] {logging_mixin.py:154} WARNING - /home/felipe/.local/lib/python3.11/site-packages/airflow/utils/email.py:154 RemovedInAirflow3Warning: Fetching SMTP credentials from configuration variables will be deprecated in a future release. Please set credentials using a connection instead.
[2024-01-19T21:49:31.004-0300] {configuration.py:1050} WARNING - section/key [smtp/smtp_user] not found in config
[2024-01-19T21:49:31.004-0300] {email.py:270} INFO - Email alerting: attempt 1
[2024-01-19T21:49:31.006-0300] {configuration.py:1050} WARNING - section/key [smtp/smtp_user] not found in config
[2024-01-19T21:49:31.006-0300] {email.py:270} INFO - Email alerting: attempt 1
[2024-01-19T21:49:31.007-0300] {taskinstance.py:2007} ERROR - Failed to send email to: ['datasetpibic@gmail.com']
Traceback (most recent call last):
  File "/home/felipe/airflow/dags/cities/sao_paulo.py", line 39, in sao_paulo
    processed_response = process_response(response)
                         ^^^^^^^^^^^^^^^^^^^^^^^^^^
  File "/home/felipe/airflow/dags/cities/sao_paulo.py", line 23, in process_response
    for linha in response['l']:
                 ~~~~~~~~^^^^^
TypeError: 'NoneType' object is not subscriptable

During handling of the above exception, another exception occurred:

Traceback (most recent call last):
  File "/home/felipe/.local/lib/python3.11/site-packages/airflow/models/taskinstance.py", line 1518, in _run_raw_task
    self._execute_task_with_callbacks(context, test_mode, session=session)
  File "/home/felipe/.local/lib/python3.11/site-packages/airflow/models/taskinstance.py", line 1681, in _execute_task_with_callbacks
    result = self._execute_task(context, task_orig)
             ^^^^^^^^^^^^^^^^^^^^^^^^^^^^^^^^^^^^^^
  File "/home/felipe/.local/lib/python3.11/site-packages/airflow/models/taskinstance.py", line 1744, in _execute_task
    result = execute_callable(context=context, **execute_callable_kwargs)
             ^^^^^^^^^^^^^^^^^^^^^^^^^^^^^^^^^^^^^^^^^^^^^^^^^^^^^^^^^^^^
  File "/home/felipe/.local/lib/python3.11/site-packages/airflow/operators/python.py", line 192, in execute
    return_value = self.execute_callable()
                   ^^^^^^^^^^^^^^^^^^^^^^^
  File "/home/felipe/.local/lib/python3.11/site-packages/airflow/operators/python.py", line 209, in execute_callable
    return self.python_callable(*self.op_args, **self.op_kwargs)
           ^^^^^^^^^^^^^^^^^^^^^^^^^^^^^^^^^^^^^^^^^^^^^^^^^^^^^
  File "/home/felipe/airflow/dags/cities/sao_paulo.py", line 43, in sao_paulo
    raise ValueError('Erro em Sao Paulo!')
ValueError: Erro em Sao Paulo!

During handling of the above exception, another exception occurred:

Traceback (most recent call last):
  File "/home/felipe/.local/lib/python3.11/site-packages/airflow/models/taskinstance.py", line 2420, in email_alert
    send_email(task.email, subject, html_content)
  File "/home/felipe/.local/lib/python3.11/site-packages/airflow/utils/email.py", line 80, in send_email
    return backend(
           ^^^^^^^^
  File "/home/felipe/.local/lib/python3.11/site-packages/airflow/utils/email.py", line 154, in send_email_smtp
    send_mime_email(e_from=mail_from, e_to=recipients, mime_msg=msg, conn_id=conn_id, dryrun=dryrun)
  File "/home/felipe/.local/lib/python3.11/site-packages/airflow/utils/email.py", line 272, in send_mime_email
    smtp_conn = _get_smtp_connection(smtp_host, smtp_port, smtp_timeout, smtp_ssl)
                ^^^^^^^^^^^^^^^^^^^^^^^^^^^^^^^^^^^^^^^^^^^^^^^^^^^^^^^^^^^^^^^^^^
  File "/home/felipe/.local/lib/python3.11/site-packages/airflow/utils/email.py", line 316, in _get_smtp_connection
    return smtplib.SMTP(host=host, port=port, timeout=timeout)
           ^^^^^^^^^^^^^^^^^^^^^^^^^^^^^^^^^^^^^^^^^^^^^^^^^^^
  File "/usr/lib/python3.11/smtplib.py", line 255, in __init__
    (code, msg) = self.connect(host, port)
                  ^^^^^^^^^^^^^^^^^^^^^^^^
  File "/usr/lib/python3.11/smtplib.py", line 341, in connect
    self.sock = self._get_socket(host, port, self.timeout)
                ^^^^^^^^^^^^^^^^^^^^^^^^^^^^^^^^^^^^^^^^^^
  File "/usr/lib/python3.11/smtplib.py", line 312, in _get_socket
    return socket.create_connection((host, port), timeout,
           ^^^^^^^^^^^^^^^^^^^^^^^^^^^^^^^^^^^^^^^^^^^^^^^
  File "/usr/lib/python3.11/socket.py", line 851, in create_connection
    raise exceptions[0]
  File "/usr/lib/python3.11/socket.py", line 836, in create_connection
    sock.connect(sa)
ConnectionRefusedError: [Errno 111] Connection refused

During handling of the above exception, another exception occurred:

Traceback (most recent call last):
  File "/home/felipe/.local/lib/python3.11/site-packages/airflow/models/taskinstance.py", line 2005, in handle_failure
    self.email_alert(error, task)
  File "/home/felipe/.local/lib/python3.11/site-packages/airflow/models/taskinstance.py", line 2422, in email_alert
    send_email(task.email, subject, html_content_err)
  File "/home/felipe/.local/lib/python3.11/site-packages/airflow/utils/email.py", line 80, in send_email
    return backend(
           ^^^^^^^^
  File "/home/felipe/.local/lib/python3.11/site-packages/airflow/utils/email.py", line 154, in send_email_smtp
    send_mime_email(e_from=mail_from, e_to=recipients, mime_msg=msg, conn_id=conn_id, dryrun=dryrun)
  File "/home/felipe/.local/lib/python3.11/site-packages/airflow/utils/email.py", line 272, in send_mime_email
    smtp_conn = _get_smtp_connection(smtp_host, smtp_port, smtp_timeout, smtp_ssl)
                ^^^^^^^^^^^^^^^^^^^^^^^^^^^^^^^^^^^^^^^^^^^^^^^^^^^^^^^^^^^^^^^^^^
  File "/home/felipe/.local/lib/python3.11/site-packages/airflow/utils/email.py", line 316, in _get_smtp_connection
    return smtplib.SMTP(host=host, port=port, timeout=timeout)
           ^^^^^^^^^^^^^^^^^^^^^^^^^^^^^^^^^^^^^^^^^^^^^^^^^^^
  File "/usr/lib/python3.11/smtplib.py", line 255, in __init__
    (code, msg) = self.connect(host, port)
                  ^^^^^^^^^^^^^^^^^^^^^^^^
  File "/usr/lib/python3.11/smtplib.py", line 341, in connect
    self.sock = self._get_socket(host, port, self.timeout)
                ^^^^^^^^^^^^^^^^^^^^^^^^^^^^^^^^^^^^^^^^^^
  File "/usr/lib/python3.11/smtplib.py", line 312, in _get_socket
    return socket.create_connection((host, port), timeout,
           ^^^^^^^^^^^^^^^^^^^^^^^^^^^^^^^^^^^^^^^^^^^^^^^
  File "/usr/lib/python3.11/socket.py", line 851, in create_connection
    raise exceptions[0]
  File "/usr/lib/python3.11/socket.py", line 836, in create_connection
    sock.connect(sa)
ConnectionRefusedError: [Errno 111] Connection refused
[2024-01-19T21:49:31.045-0300] {standard_task_runner.py:104} ERROR - Failed to execute job 4595 for task saopaulo (Erro em Sao Paulo!; 95562)
[2024-01-19T21:49:31.082-0300] {local_task_job_runner.py:228} INFO - Task exited with return code 1
[2024-01-19T21:49:31.091-0300] {taskinstance.py:2778} INFO - 1 downstream tasks scheduled from follow-on schedule check
