[2024-01-09T10:09:55.570-0300] {processor.py:157} INFO - Started process (PID=8339) to work on /home/felipe/airflow/dags/dag.py
[2024-01-09T10:09:55.571-0300] {processor.py:829} INFO - Processing file /home/felipe/airflow/dags/dag.py for tasks to queue
[2024-01-09T10:09:55.571-0300] {logging_mixin.py:154} INFO - [2024-01-09T10:09:55.571-0300] {dagbag.py:536} INFO - Filling up the DagBag from /home/felipe/airflow/dags/dag.py
[2024-01-09T10:09:56.855-0300] {logging_mixin.py:154} INFO - SAVING FILE sp
[2024-01-09T10:09:59.082-0300] {logging_mixin.py:154} INFO - SAVING FILE df
[2024-01-09T10:10:01.436-0300] {logging_mixin.py:154} INFO - SAVING FILE rj
[2024-01-09T10:10:03.088-0300] {logging_mixin.py:154} INFO - SAVING FILE cwb
[2024-01-09T10:10:03.092-0300] {processor.py:839} INFO - DAG(s) dict_keys(['cities']) retrieved from /home/felipe/airflow/dags/dag.py
[2024-01-09T10:10:03.096-0300] {logging_mixin.py:154} INFO - [2024-01-09T10:10:03.095-0300] {dag.py:2941} INFO - Sync 1 DAGs
[2024-01-09T10:10:03.106-0300] {logging_mixin.py:154} INFO - [2024-01-09T10:10:03.106-0300] {dag.py:3722} INFO - Setting next_dagrun for cities to 2024-01-09T13:09:03.105803+00:00, run_after=2024-01-09T13:10:03.105803+00:00
[2024-01-09T10:10:03.117-0300] {processor.py:179} INFO - Processing /home/felipe/airflow/dags/dag.py took 7.548 seconds
[2024-01-09T10:10:51.716-0300] {processor.py:157} INFO - Started process (PID=8598) to work on /home/felipe/airflow/dags/dag.py
[2024-01-09T10:10:51.790-0300] {processor.py:829} INFO - Processing file /home/felipe/airflow/dags/dag.py for tasks to queue
[2024-01-09T10:10:51.791-0300] {logging_mixin.py:154} INFO - [2024-01-09T10:10:51.791-0300] {dagbag.py:536} INFO - Filling up the DagBag from /home/felipe/airflow/dags/dag.py
[2024-01-09T10:10:53.036-0300] {logging_mixin.py:154} INFO - SAVING FILE sp
[2024-01-09T10:10:53.461-0300] {logging_mixin.py:154} INFO - SAVING FILE df
[2024-01-09T10:10:56.541-0300] {logging_mixin.py:154} INFO - SAVING FILE rj
[2024-01-09T10:10:58.297-0300] {logging_mixin.py:154} INFO - SAVING FILE cwb
[2024-01-09T10:10:58.300-0300] {processor.py:839} INFO - DAG(s) dict_keys(['cities']) retrieved from /home/felipe/airflow/dags/dag.py
[2024-01-09T10:10:58.309-0300] {logging_mixin.py:154} INFO - [2024-01-09T10:10:58.309-0300] {dag.py:2941} INFO - Sync 1 DAGs
[2024-01-09T10:10:58.329-0300] {logging_mixin.py:154} INFO - [2024-01-09T10:10:58.329-0300] {dag.py:3722} INFO - Setting next_dagrun for cities to 2024-01-09T13:09:58.328897+00:00, run_after=2024-01-09T13:10:58.328897+00:00
[2024-01-09T10:10:58.375-0300] {processor.py:179} INFO - Processing /home/felipe/airflow/dags/dag.py took 6.661 seconds
[2024-01-09T10:11:39.444-0300] {processor.py:157} INFO - Started process (PID=8696) to work on /home/felipe/airflow/dags/dag.py
[2024-01-09T10:11:39.476-0300] {processor.py:829} INFO - Processing file /home/felipe/airflow/dags/dag.py for tasks to queue
[2024-01-09T10:11:39.476-0300] {logging_mixin.py:154} INFO - [2024-01-09T10:11:39.476-0300] {dagbag.py:536} INFO - Filling up the DagBag from /home/felipe/airflow/dags/dag.py
[2024-01-09T10:11:40.670-0300] {logging_mixin.py:154} INFO - SAVING FILE sp
[2024-01-09T10:11:42.684-0300] {logging_mixin.py:154} INFO - SAVING FILE df
[2024-01-09T10:11:45.279-0300] {logging_mixin.py:154} INFO - SAVING FILE rj
[2024-01-09T10:11:46.088-0300] {logging_mixin.py:154} INFO - SAVING FILE cwb
[2024-01-09T10:11:46.091-0300] {processor.py:839} INFO - DAG(s) dict_keys(['cities']) retrieved from /home/felipe/airflow/dags/dag.py
[2024-01-09T10:11:46.101-0300] {logging_mixin.py:154} INFO - [2024-01-09T10:11:46.100-0300] {dag.py:2941} INFO - Sync 1 DAGs
[2024-01-09T10:11:46.115-0300] {logging_mixin.py:154} INFO - [2024-01-09T10:11:46.115-0300] {dag.py:3722} INFO - Setting next_dagrun for cities to 2024-01-09T13:10:46.115319+00:00, run_after=2024-01-09T13:11:46.115319+00:00
[2024-01-09T10:11:46.160-0300] {processor.py:179} INFO - Processing /home/felipe/airflow/dags/dag.py took 6.718 seconds
[2024-01-09T10:12:26.991-0300] {processor.py:157} INFO - Started process (PID=8798) to work on /home/felipe/airflow/dags/dag.py
[2024-01-09T10:12:27.023-0300] {processor.py:829} INFO - Processing file /home/felipe/airflow/dags/dag.py for tasks to queue
[2024-01-09T10:12:27.024-0300] {logging_mixin.py:154} INFO - [2024-01-09T10:12:27.024-0300] {dagbag.py:536} INFO - Filling up the DagBag from /home/felipe/airflow/dags/dag.py
[2024-01-09T10:12:28.246-0300] {logging_mixin.py:154} INFO - SAVING FILE sp
[2024-01-09T10:12:28.701-0300] {logging_mixin.py:154} INFO - SAVING FILE df
[2024-01-09T10:12:31.197-0300] {logging_mixin.py:154} INFO - SAVING FILE rj
[2024-01-09T10:12:31.954-0300] {logging_mixin.py:154} INFO - SAVING FILE cwb
[2024-01-09T10:12:31.956-0300] {processor.py:839} INFO - DAG(s) dict_keys(['cities']) retrieved from /home/felipe/airflow/dags/dag.py
[2024-01-09T10:12:31.966-0300] {logging_mixin.py:154} INFO - [2024-01-09T10:12:31.965-0300] {dag.py:2941} INFO - Sync 1 DAGs
[2024-01-09T10:12:31.980-0300] {logging_mixin.py:154} INFO - [2024-01-09T10:12:31.980-0300] {dag.py:3722} INFO - Setting next_dagrun for cities to 2024-01-09T13:11:31.980605+00:00, run_after=2024-01-09T13:12:31.980605+00:00
[2024-01-09T10:12:32.025-0300] {processor.py:179} INFO - Processing /home/felipe/airflow/dags/dag.py took 5.036 seconds
[2024-01-09T10:13:12.716-0300] {processor.py:157} INFO - Started process (PID=8882) to work on /home/felipe/airflow/dags/dag.py
[2024-01-09T10:13:12.787-0300] {processor.py:829} INFO - Processing file /home/felipe/airflow/dags/dag.py for tasks to queue
[2024-01-09T10:13:12.787-0300] {logging_mixin.py:154} INFO - [2024-01-09T10:13:12.787-0300] {dagbag.py:536} INFO - Filling up the DagBag from /home/felipe/airflow/dags/dag.py
[2024-01-09T10:13:13.996-0300] {logging_mixin.py:154} INFO - SAVING FILE sp
[2024-01-09T10:13:16.974-0300] {logging_mixin.py:154} INFO - SAVING FILE df
[2024-01-09T10:13:20.655-0300] {logging_mixin.py:154} INFO - SAVING FILE rj
[2024-01-09T10:13:21.416-0300] {logging_mixin.py:154} INFO - SAVING FILE cwb
[2024-01-09T10:13:21.418-0300] {processor.py:839} INFO - DAG(s) dict_keys(['cities']) retrieved from /home/felipe/airflow/dags/dag.py
[2024-01-09T10:13:21.426-0300] {logging_mixin.py:154} INFO - [2024-01-09T10:13:21.426-0300] {dag.py:2941} INFO - Sync 1 DAGs
[2024-01-09T10:13:21.437-0300] {logging_mixin.py:154} INFO - [2024-01-09T10:13:21.437-0300] {dag.py:3722} INFO - Setting next_dagrun for cities to 2024-01-09T13:12:21.437362+00:00, run_after=2024-01-09T13:13:21.437362+00:00
[2024-01-09T10:13:21.480-0300] {processor.py:179} INFO - Processing /home/felipe/airflow/dags/dag.py took 8.766 seconds
[2024-01-09T10:14:02.061-0300] {processor.py:157} INFO - Started process (PID=8960) to work on /home/felipe/airflow/dags/dag.py
[2024-01-09T10:14:02.093-0300] {processor.py:829} INFO - Processing file /home/felipe/airflow/dags/dag.py for tasks to queue
[2024-01-09T10:14:02.093-0300] {logging_mixin.py:154} INFO - [2024-01-09T10:14:02.093-0300] {dagbag.py:536} INFO - Filling up the DagBag from /home/felipe/airflow/dags/dag.py
[2024-01-09T10:14:03.343-0300] {logging_mixin.py:154} INFO - SAVING FILE sp
[2024-01-09T10:14:09.215-0300] {logging_mixin.py:154} INFO - SAVING FILE df
[2024-01-09T10:14:12.458-0300] {logging_mixin.py:154} INFO - SAVING FILE rj
[2024-01-09T10:14:13.227-0300] {logging_mixin.py:154} INFO - SAVING FILE cwb
[2024-01-09T10:14:13.230-0300] {processor.py:839} INFO - DAG(s) dict_keys(['cities']) retrieved from /home/felipe/airflow/dags/dag.py
[2024-01-09T10:14:13.239-0300] {logging_mixin.py:154} INFO - [2024-01-09T10:14:13.238-0300] {dag.py:2941} INFO - Sync 1 DAGs
[2024-01-09T10:14:13.253-0300] {logging_mixin.py:154} INFO - [2024-01-09T10:14:13.253-0300] {dag.py:3722} INFO - Setting next_dagrun for cities to 2024-01-09T13:13:13.253355+00:00, run_after=2024-01-09T13:14:13.253355+00:00
[2024-01-09T10:14:13.299-0300] {processor.py:179} INFO - Processing /home/felipe/airflow/dags/dag.py took 11.240 seconds
[2024-01-09T10:14:57.809-0300] {processor.py:157} INFO - Started process (PID=9050) to work on /home/felipe/airflow/dags/dag.py
[2024-01-09T10:14:57.841-0300] {processor.py:829} INFO - Processing file /home/felipe/airflow/dags/dag.py for tasks to queue
[2024-01-09T10:14:57.842-0300] {logging_mixin.py:154} INFO - [2024-01-09T10:14:57.841-0300] {dagbag.py:536} INFO - Filling up the DagBag from /home/felipe/airflow/dags/dag.py
[2024-01-09T10:14:59.148-0300] {logging_mixin.py:154} INFO - SAVING FILE sp
[2024-01-09T10:15:02.942-0300] {logging_mixin.py:154} INFO - SAVING FILE df
[2024-01-09T10:15:06.811-0300] {logging_mixin.py:154} INFO - SAVING FILE rj
[2024-01-09T10:15:08.575-0300] {logging_mixin.py:154} INFO - SAVING FILE cwb
[2024-01-09T10:15:08.577-0300] {processor.py:839} INFO - DAG(s) dict_keys(['cities']) retrieved from /home/felipe/airflow/dags/dag.py
[2024-01-09T10:15:08.583-0300] {logging_mixin.py:154} INFO - [2024-01-09T10:15:08.583-0300] {dag.py:2941} INFO - Sync 1 DAGs
[2024-01-09T10:15:08.593-0300] {logging_mixin.py:154} INFO - [2024-01-09T10:15:08.593-0300] {dag.py:3722} INFO - Setting next_dagrun for cities to 2024-01-09T13:14:08.592910+00:00, run_after=2024-01-09T13:15:08.592910+00:00
[2024-01-09T10:15:08.644-0300] {processor.py:179} INFO - Processing /home/felipe/airflow/dags/dag.py took 10.837 seconds
[2024-01-09T10:17:30.155-0300] {processor.py:157} INFO - Started process (PID=9367) to work on /home/felipe/airflow/dags/dag.py
[2024-01-09T10:17:30.156-0300] {processor.py:829} INFO - Processing file /home/felipe/airflow/dags/dag.py for tasks to queue
[2024-01-09T10:17:30.156-0300] {logging_mixin.py:154} INFO - [2024-01-09T10:17:30.156-0300] {dagbag.py:536} INFO - Filling up the DagBag from /home/felipe/airflow/dags/dag.py
[2024-01-09T10:17:31.395-0300] {logging_mixin.py:154} INFO - SAVING FILE sp
[2024-01-09T10:17:31.823-0300] {logging_mixin.py:154} INFO - SAVING FILE df
[2024-01-09T10:17:34.146-0300] {logging_mixin.py:154} INFO - SAVING FILE rj
[2024-01-09T10:17:35.722-0300] {logging_mixin.py:154} INFO - SAVING FILE cwb
[2024-01-09T10:17:35.724-0300] {processor.py:839} INFO - DAG(s) dict_keys(['cities']) retrieved from /home/felipe/airflow/dags/dag.py
[2024-01-09T10:17:35.731-0300] {logging_mixin.py:154} INFO - [2024-01-09T10:17:35.731-0300] {dag.py:2941} INFO - Sync 1 DAGs
[2024-01-09T10:17:35.738-0300] {logging_mixin.py:154} INFO - [2024-01-09T10:17:35.738-0300] {dag.py:3722} INFO - Setting next_dagrun for cities to 2024-01-09T13:16:35.738207+00:00, run_after=2024-01-09T13:17:35.738207+00:00
[2024-01-09T10:17:35.778-0300] {processor.py:179} INFO - Processing /home/felipe/airflow/dags/dag.py took 5.626 seconds
[2024-01-09T10:38:04.568-0300] {processor.py:157} INFO - Started process (PID=11741) to work on /home/felipe/airflow/dags/dag.py
[2024-01-09T10:38:04.600-0300] {processor.py:829} INFO - Processing file /home/felipe/airflow/dags/dag.py for tasks to queue
[2024-01-09T10:38:04.601-0300] {logging_mixin.py:154} INFO - [2024-01-09T10:38:04.600-0300] {dagbag.py:536} INFO - Filling up the DagBag from /home/felipe/airflow/dags/dag.py
[2024-01-09T10:38:04.856-0300] {logging_mixin.py:154} INFO - sao_paulo - Error: HTTPConnectionPool(host='api.olhovivo.sptrans.com.br', port=80): Max retries exceeded with url: /v2.1/Login/Autenticar?token=d1bb804b2deb44121c369766969557fac53d34fa4b595f884c13f81ca6de5245 (Caused by NewConnectionError('<urllib3.connection.HTTPConnection object at 0x7f93c19bfe50>: Failed to establish a new connection: [Errno -3] Temporary failure in name resolution'))
[2024-01-09T10:38:04.858-0300] {logging_mixin.py:154} INFO - [2024-01-09T10:38:04.856-0300] {dagbag.py:346} ERROR - Failed to import: /home/felipe/airflow/dags/dag.py
Traceback (most recent call last):
  File "/home/felipe/.local/lib/python3.11/site-packages/urllib3/connection.py", line 174, in _new_conn
    conn = connection.create_connection(
           ^^^^^^^^^^^^^^^^^^^^^^^^^^^^^
  File "/home/felipe/.local/lib/python3.11/site-packages/urllib3/util/connection.py", line 72, in create_connection
    for res in socket.getaddrinfo(host, port, family, socket.SOCK_STREAM):
               ^^^^^^^^^^^^^^^^^^^^^^^^^^^^^^^^^^^^^^^^^^^^^^^^^^^^^^^^^^
  File "/usr/lib/python3.11/socket.py", line 962, in getaddrinfo
    for res in _socket.getaddrinfo(host, port, family, type, proto, flags):
               ^^^^^^^^^^^^^^^^^^^^^^^^^^^^^^^^^^^^^^^^^^^^^^^^^^^^^^^^^^^
socket.gaierror: [Errno -3] Temporary failure in name resolution

During handling of the above exception, another exception occurred:

Traceback (most recent call last):
  File "/home/felipe/.local/lib/python3.11/site-packages/urllib3/connectionpool.py", line 715, in urlopen
    httplib_response = self._make_request(
                       ^^^^^^^^^^^^^^^^^^^
  File "/home/felipe/.local/lib/python3.11/site-packages/urllib3/connectionpool.py", line 416, in _make_request
    conn.request(method, url, **httplib_request_kw)
  File "/home/felipe/.local/lib/python3.11/site-packages/urllib3/connection.py", line 244, in request
    super(HTTPConnection, self).request(method, url, body=body, headers=headers)
  File "/usr/lib/python3.11/http/client.py", line 1286, in request
    self._send_request(method, url, body, headers, encode_chunked)
  File "/usr/lib/python3.11/http/client.py", line 1332, in _send_request
    self.endheaders(body, encode_chunked=encode_chunked)
  File "/usr/lib/python3.11/http/client.py", line 1281, in endheaders
    self._send_output(message_body, encode_chunked=encode_chunked)
  File "/usr/lib/python3.11/http/client.py", line 1041, in _send_output
    self.send(msg)
  File "/usr/lib/python3.11/http/client.py", line 979, in send
    self.connect()
  File "/home/felipe/.local/lib/python3.11/site-packages/urllib3/connection.py", line 205, in connect
    conn = self._new_conn()
           ^^^^^^^^^^^^^^^^
  File "/home/felipe/.local/lib/python3.11/site-packages/urllib3/connection.py", line 186, in _new_conn
    raise NewConnectionError(
urllib3.exceptions.NewConnectionError: <urllib3.connection.HTTPConnection object at 0x7f93c19bfe50>: Failed to establish a new connection: [Errno -3] Temporary failure in name resolution

During handling of the above exception, another exception occurred:

Traceback (most recent call last):
  File "/home/felipe/.local/lib/python3.11/site-packages/requests/adapters.py", line 486, in send
    resp = conn.urlopen(
           ^^^^^^^^^^^^^
  File "/home/felipe/.local/lib/python3.11/site-packages/urllib3/connectionpool.py", line 799, in urlopen
    retries = retries.increment(
              ^^^^^^^^^^^^^^^^^^
  File "/home/felipe/.local/lib/python3.11/site-packages/urllib3/util/retry.py", line 592, in increment
    raise MaxRetryError(_pool, url, error or ResponseError(cause))
urllib3.exceptions.MaxRetryError: HTTPConnectionPool(host='api.olhovivo.sptrans.com.br', port=80): Max retries exceeded with url: /v2.1/Login/Autenticar?token=d1bb804b2deb44121c369766969557fac53d34fa4b595f884c13f81ca6de5245 (Caused by NewConnectionError('<urllib3.connection.HTTPConnection object at 0x7f93c19bfe50>: Failed to establish a new connection: [Errno -3] Temporary failure in name resolution'))

During handling of the above exception, another exception occurred:

Traceback (most recent call last):
  File "/home/felipe/airflow/dags/cities/sao_paulo.py", line 36, in sao_paulo
    response = req()
               ^^^^^
  File "/home/felipe/airflow/dags/cities/sao_paulo.py", line 10, in req
    auth = requests.post(url=(API_URL + "/Login/Autenticar?token=" + TOKEN))
           ^^^^^^^^^^^^^^^^^^^^^^^^^^^^^^^^^^^^^^^^^^^^^^^^^^^^^^^^^^^^^^^^^
  File "/home/felipe/.local/lib/python3.11/site-packages/requests/api.py", line 115, in post
    return request("post", url, data=data, json=json, **kwargs)
           ^^^^^^^^^^^^^^^^^^^^^^^^^^^^^^^^^^^^^^^^^^^^^^^^^^^^
  File "/home/felipe/.local/lib/python3.11/site-packages/requests/api.py", line 59, in request
    return session.request(method=method, url=url, **kwargs)
           ^^^^^^^^^^^^^^^^^^^^^^^^^^^^^^^^^^^^^^^^^^^^^^^^^
  File "/home/felipe/.local/lib/python3.11/site-packages/requests/sessions.py", line 589, in request
    resp = self.send(prep, **send_kwargs)
           ^^^^^^^^^^^^^^^^^^^^^^^^^^^^^^
  File "/home/felipe/.local/lib/python3.11/site-packages/requests/sessions.py", line 703, in send
    r = adapter.send(request, **kwargs)
        ^^^^^^^^^^^^^^^^^^^^^^^^^^^^^^^
  File "/home/felipe/.local/lib/python3.11/site-packages/requests/adapters.py", line 519, in send
    raise ConnectionError(e, request=request)
requests.exceptions.ConnectionError: HTTPConnectionPool(host='api.olhovivo.sptrans.com.br', port=80): Max retries exceeded with url: /v2.1/Login/Autenticar?token=d1bb804b2deb44121c369766969557fac53d34fa4b595f884c13f81ca6de5245 (Caused by NewConnectionError('<urllib3.connection.HTTPConnection object at 0x7f93c19bfe50>: Failed to establish a new connection: [Errno -3] Temporary failure in name resolution'))

During handling of the above exception, another exception occurred:

Traceback (most recent call last):
  File "/home/felipe/.local/lib/python3.11/site-packages/airflow/models/dagbag.py", line 342, in parse
    loader.exec_module(new_module)
  File "<frozen importlib._bootstrap_external>", line 940, in exec_module
  File "<frozen importlib._bootstrap>", line 241, in _call_with_frames_removed
  File "/home/felipe/airflow/dags/dag.py", line 7, in <module>
    from cities.sao_paulo import sao_paulo
  File "/home/felipe/airflow/dags/cities/sao_paulo.py", line 43, in <module>
    sao_paulo()
  File "/home/felipe/airflow/dags/cities/sao_paulo.py", line 41, in sao_paulo
    raise ValueError('Erro em Sao Paulo!')
ValueError: Erro em Sao Paulo!
[2024-01-09T10:38:04.859-0300] {processor.py:841} WARNING - No viable dags retrieved from /home/felipe/airflow/dags/dag.py
[2024-01-09T10:38:04.896-0300] {processor.py:179} INFO - Processing /home/felipe/airflow/dags/dag.py took 0.330 seconds
[2024-01-09T10:38:35.695-0300] {processor.py:157} INFO - Started process (PID=11804) to work on /home/felipe/airflow/dags/dag.py
[2024-01-09T10:38:35.727-0300] {processor.py:829} INFO - Processing file /home/felipe/airflow/dags/dag.py for tasks to queue
[2024-01-09T10:38:35.727-0300] {logging_mixin.py:154} INFO - [2024-01-09T10:38:35.727-0300] {dagbag.py:536} INFO - Filling up the DagBag from /home/felipe/airflow/dags/dag.py
[2024-01-09T10:38:35.983-0300] {logging_mixin.py:154} INFO - sao_paulo - Error: HTTPConnectionPool(host='api.olhovivo.sptrans.com.br', port=80): Max retries exceeded with url: /v2.1/Login/Autenticar?token=d1bb804b2deb44121c369766969557fac53d34fa4b595f884c13f81ca6de5245 (Caused by NewConnectionError('<urllib3.connection.HTTPConnection object at 0x7f93dfd0bf10>: Failed to establish a new connection: [Errno -3] Temporary failure in name resolution'))
[2024-01-09T10:38:35.985-0300] {logging_mixin.py:154} INFO - [2024-01-09T10:38:35.983-0300] {dagbag.py:346} ERROR - Failed to import: /home/felipe/airflow/dags/dag.py
Traceback (most recent call last):
  File "/home/felipe/.local/lib/python3.11/site-packages/urllib3/connection.py", line 174, in _new_conn
    conn = connection.create_connection(
           ^^^^^^^^^^^^^^^^^^^^^^^^^^^^^
  File "/home/felipe/.local/lib/python3.11/site-packages/urllib3/util/connection.py", line 72, in create_connection
    for res in socket.getaddrinfo(host, port, family, socket.SOCK_STREAM):
               ^^^^^^^^^^^^^^^^^^^^^^^^^^^^^^^^^^^^^^^^^^^^^^^^^^^^^^^^^^
  File "/usr/lib/python3.11/socket.py", line 962, in getaddrinfo
    for res in _socket.getaddrinfo(host, port, family, type, proto, flags):
               ^^^^^^^^^^^^^^^^^^^^^^^^^^^^^^^^^^^^^^^^^^^^^^^^^^^^^^^^^^^
socket.gaierror: [Errno -3] Temporary failure in name resolution

During handling of the above exception, another exception occurred:

Traceback (most recent call last):
  File "/home/felipe/.local/lib/python3.11/site-packages/urllib3/connectionpool.py", line 715, in urlopen
    httplib_response = self._make_request(
                       ^^^^^^^^^^^^^^^^^^^
  File "/home/felipe/.local/lib/python3.11/site-packages/urllib3/connectionpool.py", line 416, in _make_request
    conn.request(method, url, **httplib_request_kw)
  File "/home/felipe/.local/lib/python3.11/site-packages/urllib3/connection.py", line 244, in request
    super(HTTPConnection, self).request(method, url, body=body, headers=headers)
  File "/usr/lib/python3.11/http/client.py", line 1286, in request
    self._send_request(method, url, body, headers, encode_chunked)
  File "/usr/lib/python3.11/http/client.py", line 1332, in _send_request
    self.endheaders(body, encode_chunked=encode_chunked)
  File "/usr/lib/python3.11/http/client.py", line 1281, in endheaders
    self._send_output(message_body, encode_chunked=encode_chunked)
  File "/usr/lib/python3.11/http/client.py", line 1041, in _send_output
    self.send(msg)
  File "/usr/lib/python3.11/http/client.py", line 979, in send
    self.connect()
  File "/home/felipe/.local/lib/python3.11/site-packages/urllib3/connection.py", line 205, in connect
    conn = self._new_conn()
           ^^^^^^^^^^^^^^^^
  File "/home/felipe/.local/lib/python3.11/site-packages/urllib3/connection.py", line 186, in _new_conn
    raise NewConnectionError(
urllib3.exceptions.NewConnectionError: <urllib3.connection.HTTPConnection object at 0x7f93dfd0bf10>: Failed to establish a new connection: [Errno -3] Temporary failure in name resolution

During handling of the above exception, another exception occurred:

Traceback (most recent call last):
  File "/home/felipe/.local/lib/python3.11/site-packages/requests/adapters.py", line 486, in send
    resp = conn.urlopen(
           ^^^^^^^^^^^^^
  File "/home/felipe/.local/lib/python3.11/site-packages/urllib3/connectionpool.py", line 799, in urlopen
    retries = retries.increment(
              ^^^^^^^^^^^^^^^^^^
  File "/home/felipe/.local/lib/python3.11/site-packages/urllib3/util/retry.py", line 592, in increment
    raise MaxRetryError(_pool, url, error or ResponseError(cause))
urllib3.exceptions.MaxRetryError: HTTPConnectionPool(host='api.olhovivo.sptrans.com.br', port=80): Max retries exceeded with url: /v2.1/Login/Autenticar?token=d1bb804b2deb44121c369766969557fac53d34fa4b595f884c13f81ca6de5245 (Caused by NewConnectionError('<urllib3.connection.HTTPConnection object at 0x7f93dfd0bf10>: Failed to establish a new connection: [Errno -3] Temporary failure in name resolution'))

During handling of the above exception, another exception occurred:

Traceback (most recent call last):
  File "/home/felipe/airflow/dags/cities/sao_paulo.py", line 36, in sao_paulo
    response = req()
               ^^^^^
  File "/home/felipe/airflow/dags/cities/sao_paulo.py", line 10, in req
    auth = requests.post(url=(API_URL + "/Login/Autenticar?token=" + TOKEN))
           ^^^^^^^^^^^^^^^^^^^^^^^^^^^^^^^^^^^^^^^^^^^^^^^^^^^^^^^^^^^^^^^^^
  File "/home/felipe/.local/lib/python3.11/site-packages/requests/api.py", line 115, in post
    return request("post", url, data=data, json=json, **kwargs)
           ^^^^^^^^^^^^^^^^^^^^^^^^^^^^^^^^^^^^^^^^^^^^^^^^^^^^
  File "/home/felipe/.local/lib/python3.11/site-packages/requests/api.py", line 59, in request
    return session.request(method=method, url=url, **kwargs)
           ^^^^^^^^^^^^^^^^^^^^^^^^^^^^^^^^^^^^^^^^^^^^^^^^^
  File "/home/felipe/.local/lib/python3.11/site-packages/requests/sessions.py", line 589, in request
    resp = self.send(prep, **send_kwargs)
           ^^^^^^^^^^^^^^^^^^^^^^^^^^^^^^
  File "/home/felipe/.local/lib/python3.11/site-packages/requests/sessions.py", line 703, in send
    r = adapter.send(request, **kwargs)
        ^^^^^^^^^^^^^^^^^^^^^^^^^^^^^^^
  File "/home/felipe/.local/lib/python3.11/site-packages/requests/adapters.py", line 519, in send
    raise ConnectionError(e, request=request)
requests.exceptions.ConnectionError: HTTPConnectionPool(host='api.olhovivo.sptrans.com.br', port=80): Max retries exceeded with url: /v2.1/Login/Autenticar?token=d1bb804b2deb44121c369766969557fac53d34fa4b595f884c13f81ca6de5245 (Caused by NewConnectionError('<urllib3.connection.HTTPConnection object at 0x7f93dfd0bf10>: Failed to establish a new connection: [Errno -3] Temporary failure in name resolution'))

During handling of the above exception, another exception occurred:

Traceback (most recent call last):
  File "/home/felipe/.local/lib/python3.11/site-packages/airflow/models/dagbag.py", line 342, in parse
    loader.exec_module(new_module)
  File "<frozen importlib._bootstrap_external>", line 940, in exec_module
  File "<frozen importlib._bootstrap>", line 241, in _call_with_frames_removed
  File "/home/felipe/airflow/dags/dag.py", line 7, in <module>
    from cities.sao_paulo import sao_paulo
  File "/home/felipe/airflow/dags/cities/sao_paulo.py", line 43, in <module>
    sao_paulo()
  File "/home/felipe/airflow/dags/cities/sao_paulo.py", line 41, in sao_paulo
    raise ValueError('Erro em Sao Paulo!')
ValueError: Erro em Sao Paulo!
[2024-01-09T10:38:35.986-0300] {processor.py:841} WARNING - No viable dags retrieved from /home/felipe/airflow/dags/dag.py
[2024-01-09T10:38:36.023-0300] {processor.py:179} INFO - Processing /home/felipe/airflow/dags/dag.py took 0.331 seconds
[2024-01-09T10:39:17.092-0300] {processor.py:157} INFO - Started process (PID=11878) to work on /home/felipe/airflow/dags/dag.py
[2024-01-09T10:39:17.093-0300] {processor.py:829} INFO - Processing file /home/felipe/airflow/dags/dag.py for tasks to queue
[2024-01-09T10:39:17.093-0300] {logging_mixin.py:154} INFO - [2024-01-09T10:39:17.093-0300] {dagbag.py:536} INFO - Filling up the DagBag from /home/felipe/airflow/dags/dag.py
[2024-01-09T10:39:17.346-0300] {logging_mixin.py:154} INFO - sao_paulo - Error: HTTPConnectionPool(host='api.olhovivo.sptrans.com.br', port=80): Max retries exceeded with url: /v2.1/Login/Autenticar?token=d1bb804b2deb44121c369766969557fac53d34fa4b595f884c13f81ca6de5245 (Caused by NewConnectionError('<urllib3.connection.HTTPConnection object at 0x7f93c1989390>: Failed to establish a new connection: [Errno -3] Temporary failure in name resolution'))
[2024-01-09T10:39:17.348-0300] {logging_mixin.py:154} INFO - [2024-01-09T10:39:17.346-0300] {dagbag.py:346} ERROR - Failed to import: /home/felipe/airflow/dags/dag.py
Traceback (most recent call last):
  File "/home/felipe/.local/lib/python3.11/site-packages/urllib3/connection.py", line 174, in _new_conn
    conn = connection.create_connection(
           ^^^^^^^^^^^^^^^^^^^^^^^^^^^^^
  File "/home/felipe/.local/lib/python3.11/site-packages/urllib3/util/connection.py", line 72, in create_connection
    for res in socket.getaddrinfo(host, port, family, socket.SOCK_STREAM):
               ^^^^^^^^^^^^^^^^^^^^^^^^^^^^^^^^^^^^^^^^^^^^^^^^^^^^^^^^^^
  File "/usr/lib/python3.11/socket.py", line 962, in getaddrinfo
    for res in _socket.getaddrinfo(host, port, family, type, proto, flags):
               ^^^^^^^^^^^^^^^^^^^^^^^^^^^^^^^^^^^^^^^^^^^^^^^^^^^^^^^^^^^
socket.gaierror: [Errno -3] Temporary failure in name resolution

During handling of the above exception, another exception occurred:

Traceback (most recent call last):
  File "/home/felipe/.local/lib/python3.11/site-packages/urllib3/connectionpool.py", line 715, in urlopen
    httplib_response = self._make_request(
                       ^^^^^^^^^^^^^^^^^^^
  File "/home/felipe/.local/lib/python3.11/site-packages/urllib3/connectionpool.py", line 416, in _make_request
    conn.request(method, url, **httplib_request_kw)
  File "/home/felipe/.local/lib/python3.11/site-packages/urllib3/connection.py", line 244, in request
    super(HTTPConnection, self).request(method, url, body=body, headers=headers)
  File "/usr/lib/python3.11/http/client.py", line 1286, in request
    self._send_request(method, url, body, headers, encode_chunked)
  File "/usr/lib/python3.11/http/client.py", line 1332, in _send_request
    self.endheaders(body, encode_chunked=encode_chunked)
  File "/usr/lib/python3.11/http/client.py", line 1281, in endheaders
    self._send_output(message_body, encode_chunked=encode_chunked)
  File "/usr/lib/python3.11/http/client.py", line 1041, in _send_output
    self.send(msg)
  File "/usr/lib/python3.11/http/client.py", line 979, in send
    self.connect()
  File "/home/felipe/.local/lib/python3.11/site-packages/urllib3/connection.py", line 205, in connect
    conn = self._new_conn()
           ^^^^^^^^^^^^^^^^
  File "/home/felipe/.local/lib/python3.11/site-packages/urllib3/connection.py", line 186, in _new_conn
    raise NewConnectionError(
urllib3.exceptions.NewConnectionError: <urllib3.connection.HTTPConnection object at 0x7f93c1989390>: Failed to establish a new connection: [Errno -3] Temporary failure in name resolution

During handling of the above exception, another exception occurred:

Traceback (most recent call last):
  File "/home/felipe/.local/lib/python3.11/site-packages/requests/adapters.py", line 486, in send
    resp = conn.urlopen(
           ^^^^^^^^^^^^^
  File "/home/felipe/.local/lib/python3.11/site-packages/urllib3/connectionpool.py", line 799, in urlopen
    retries = retries.increment(
              ^^^^^^^^^^^^^^^^^^
  File "/home/felipe/.local/lib/python3.11/site-packages/urllib3/util/retry.py", line 592, in increment
    raise MaxRetryError(_pool, url, error or ResponseError(cause))
urllib3.exceptions.MaxRetryError: HTTPConnectionPool(host='api.olhovivo.sptrans.com.br', port=80): Max retries exceeded with url: /v2.1/Login/Autenticar?token=d1bb804b2deb44121c369766969557fac53d34fa4b595f884c13f81ca6de5245 (Caused by NewConnectionError('<urllib3.connection.HTTPConnection object at 0x7f93c1989390>: Failed to establish a new connection: [Errno -3] Temporary failure in name resolution'))

During handling of the above exception, another exception occurred:

Traceback (most recent call last):
  File "/home/felipe/airflow/dags/cities/sao_paulo.py", line 36, in sao_paulo
    response = req()
               ^^^^^
  File "/home/felipe/airflow/dags/cities/sao_paulo.py", line 10, in req
    auth = requests.post(url=(API_URL + "/Login/Autenticar?token=" + TOKEN))
           ^^^^^^^^^^^^^^^^^^^^^^^^^^^^^^^^^^^^^^^^^^^^^^^^^^^^^^^^^^^^^^^^^
  File "/home/felipe/.local/lib/python3.11/site-packages/requests/api.py", line 115, in post
    return request("post", url, data=data, json=json, **kwargs)
           ^^^^^^^^^^^^^^^^^^^^^^^^^^^^^^^^^^^^^^^^^^^^^^^^^^^^
  File "/home/felipe/.local/lib/python3.11/site-packages/requests/api.py", line 59, in request
    return session.request(method=method, url=url, **kwargs)
           ^^^^^^^^^^^^^^^^^^^^^^^^^^^^^^^^^^^^^^^^^^^^^^^^^
  File "/home/felipe/.local/lib/python3.11/site-packages/requests/sessions.py", line 589, in request
    resp = self.send(prep, **send_kwargs)
           ^^^^^^^^^^^^^^^^^^^^^^^^^^^^^^
  File "/home/felipe/.local/lib/python3.11/site-packages/requests/sessions.py", line 703, in send
    r = adapter.send(request, **kwargs)
        ^^^^^^^^^^^^^^^^^^^^^^^^^^^^^^^
  File "/home/felipe/.local/lib/python3.11/site-packages/requests/adapters.py", line 519, in send
    raise ConnectionError(e, request=request)
requests.exceptions.ConnectionError: HTTPConnectionPool(host='api.olhovivo.sptrans.com.br', port=80): Max retries exceeded with url: /v2.1/Login/Autenticar?token=d1bb804b2deb44121c369766969557fac53d34fa4b595f884c13f81ca6de5245 (Caused by NewConnectionError('<urllib3.connection.HTTPConnection object at 0x7f93c1989390>: Failed to establish a new connection: [Errno -3] Temporary failure in name resolution'))

During handling of the above exception, another exception occurred:

Traceback (most recent call last):
  File "/home/felipe/.local/lib/python3.11/site-packages/airflow/models/dagbag.py", line 342, in parse
    loader.exec_module(new_module)
  File "<frozen importlib._bootstrap_external>", line 940, in exec_module
  File "<frozen importlib._bootstrap>", line 241, in _call_with_frames_removed
  File "/home/felipe/airflow/dags/dag.py", line 7, in <module>
    from cities.sao_paulo import sao_paulo
  File "/home/felipe/airflow/dags/cities/sao_paulo.py", line 43, in <module>
    sao_paulo()
  File "/home/felipe/airflow/dags/cities/sao_paulo.py", line 41, in sao_paulo
    raise ValueError('Erro em Sao Paulo!')
ValueError: Erro em Sao Paulo!
[2024-01-09T10:39:17.349-0300] {processor.py:841} WARNING - No viable dags retrieved from /home/felipe/airflow/dags/dag.py
[2024-01-09T10:39:17.386-0300] {processor.py:179} INFO - Processing /home/felipe/airflow/dags/dag.py took 0.296 seconds
[2024-01-09T10:39:54.836-0300] {processor.py:157} INFO - Started process (PID=11952) to work on /home/felipe/airflow/dags/dag.py
[2024-01-09T10:39:54.868-0300] {processor.py:829} INFO - Processing file /home/felipe/airflow/dags/dag.py for tasks to queue
[2024-01-09T10:39:54.869-0300] {logging_mixin.py:154} INFO - [2024-01-09T10:39:54.869-0300] {dagbag.py:536} INFO - Filling up the DagBag from /home/felipe/airflow/dags/dag.py
[2024-01-09T10:39:55.120-0300] {logging_mixin.py:154} INFO - sao_paulo - Error: HTTPConnectionPool(host='api.olhovivo.sptrans.com.br', port=80): Max retries exceeded with url: /v2.1/Login/Autenticar?token=d1bb804b2deb44121c369766969557fac53d34fa4b595f884c13f81ca6de5245 (Caused by NewConnectionError('<urllib3.connection.HTTPConnection object at 0x7f93bf9952d0>: Failed to establish a new connection: [Errno -3] Temporary failure in name resolution'))
[2024-01-09T10:39:55.122-0300] {logging_mixin.py:154} INFO - [2024-01-09T10:39:55.120-0300] {dagbag.py:346} ERROR - Failed to import: /home/felipe/airflow/dags/dag.py
Traceback (most recent call last):
  File "/home/felipe/.local/lib/python3.11/site-packages/urllib3/connection.py", line 174, in _new_conn
    conn = connection.create_connection(
           ^^^^^^^^^^^^^^^^^^^^^^^^^^^^^
  File "/home/felipe/.local/lib/python3.11/site-packages/urllib3/util/connection.py", line 72, in create_connection
    for res in socket.getaddrinfo(host, port, family, socket.SOCK_STREAM):
               ^^^^^^^^^^^^^^^^^^^^^^^^^^^^^^^^^^^^^^^^^^^^^^^^^^^^^^^^^^
  File "/usr/lib/python3.11/socket.py", line 962, in getaddrinfo
    for res in _socket.getaddrinfo(host, port, family, type, proto, flags):
               ^^^^^^^^^^^^^^^^^^^^^^^^^^^^^^^^^^^^^^^^^^^^^^^^^^^^^^^^^^^
socket.gaierror: [Errno -3] Temporary failure in name resolution

During handling of the above exception, another exception occurred:

Traceback (most recent call last):
  File "/home/felipe/.local/lib/python3.11/site-packages/urllib3/connectionpool.py", line 715, in urlopen
    httplib_response = self._make_request(
                       ^^^^^^^^^^^^^^^^^^^
  File "/home/felipe/.local/lib/python3.11/site-packages/urllib3/connectionpool.py", line 416, in _make_request
    conn.request(method, url, **httplib_request_kw)
  File "/home/felipe/.local/lib/python3.11/site-packages/urllib3/connection.py", line 244, in request
    super(HTTPConnection, self).request(method, url, body=body, headers=headers)
  File "/usr/lib/python3.11/http/client.py", line 1286, in request
    self._send_request(method, url, body, headers, encode_chunked)
  File "/usr/lib/python3.11/http/client.py", line 1332, in _send_request
    self.endheaders(body, encode_chunked=encode_chunked)
  File "/usr/lib/python3.11/http/client.py", line 1281, in endheaders
    self._send_output(message_body, encode_chunked=encode_chunked)
  File "/usr/lib/python3.11/http/client.py", line 1041, in _send_output
    self.send(msg)
  File "/usr/lib/python3.11/http/client.py", line 979, in send
    self.connect()
  File "/home/felipe/.local/lib/python3.11/site-packages/urllib3/connection.py", line 205, in connect
    conn = self._new_conn()
           ^^^^^^^^^^^^^^^^
  File "/home/felipe/.local/lib/python3.11/site-packages/urllib3/connection.py", line 186, in _new_conn
    raise NewConnectionError(
urllib3.exceptions.NewConnectionError: <urllib3.connection.HTTPConnection object at 0x7f93bf9952d0>: Failed to establish a new connection: [Errno -3] Temporary failure in name resolution

During handling of the above exception, another exception occurred:

Traceback (most recent call last):
  File "/home/felipe/.local/lib/python3.11/site-packages/requests/adapters.py", line 486, in send
    resp = conn.urlopen(
           ^^^^^^^^^^^^^
  File "/home/felipe/.local/lib/python3.11/site-packages/urllib3/connectionpool.py", line 799, in urlopen
    retries = retries.increment(
              ^^^^^^^^^^^^^^^^^^
  File "/home/felipe/.local/lib/python3.11/site-packages/urllib3/util/retry.py", line 592, in increment
    raise MaxRetryError(_pool, url, error or ResponseError(cause))
urllib3.exceptions.MaxRetryError: HTTPConnectionPool(host='api.olhovivo.sptrans.com.br', port=80): Max retries exceeded with url: /v2.1/Login/Autenticar?token=d1bb804b2deb44121c369766969557fac53d34fa4b595f884c13f81ca6de5245 (Caused by NewConnectionError('<urllib3.connection.HTTPConnection object at 0x7f93bf9952d0>: Failed to establish a new connection: [Errno -3] Temporary failure in name resolution'))

During handling of the above exception, another exception occurred:

Traceback (most recent call last):
  File "/home/felipe/airflow/dags/cities/sao_paulo.py", line 36, in sao_paulo
    response = req()
               ^^^^^
  File "/home/felipe/airflow/dags/cities/sao_paulo.py", line 10, in req
    auth = requests.post(url=(API_URL + "/Login/Autenticar?token=" + TOKEN))
           ^^^^^^^^^^^^^^^^^^^^^^^^^^^^^^^^^^^^^^^^^^^^^^^^^^^^^^^^^^^^^^^^^
  File "/home/felipe/.local/lib/python3.11/site-packages/requests/api.py", line 115, in post
    return request("post", url, data=data, json=json, **kwargs)
           ^^^^^^^^^^^^^^^^^^^^^^^^^^^^^^^^^^^^^^^^^^^^^^^^^^^^
  File "/home/felipe/.local/lib/python3.11/site-packages/requests/api.py", line 59, in request
    return session.request(method=method, url=url, **kwargs)
           ^^^^^^^^^^^^^^^^^^^^^^^^^^^^^^^^^^^^^^^^^^^^^^^^^
  File "/home/felipe/.local/lib/python3.11/site-packages/requests/sessions.py", line 589, in request
    resp = self.send(prep, **send_kwargs)
           ^^^^^^^^^^^^^^^^^^^^^^^^^^^^^^
  File "/home/felipe/.local/lib/python3.11/site-packages/requests/sessions.py", line 703, in send
    r = adapter.send(request, **kwargs)
        ^^^^^^^^^^^^^^^^^^^^^^^^^^^^^^^
  File "/home/felipe/.local/lib/python3.11/site-packages/requests/adapters.py", line 519, in send
    raise ConnectionError(e, request=request)
requests.exceptions.ConnectionError: HTTPConnectionPool(host='api.olhovivo.sptrans.com.br', port=80): Max retries exceeded with url: /v2.1/Login/Autenticar?token=d1bb804b2deb44121c369766969557fac53d34fa4b595f884c13f81ca6de5245 (Caused by NewConnectionError('<urllib3.connection.HTTPConnection object at 0x7f93bf9952d0>: Failed to establish a new connection: [Errno -3] Temporary failure in name resolution'))

During handling of the above exception, another exception occurred:

Traceback (most recent call last):
  File "/home/felipe/.local/lib/python3.11/site-packages/airflow/models/dagbag.py", line 342, in parse
    loader.exec_module(new_module)
  File "<frozen importlib._bootstrap_external>", line 940, in exec_module
  File "<frozen importlib._bootstrap>", line 241, in _call_with_frames_removed
  File "/home/felipe/airflow/dags/dag.py", line 7, in <module>
    from cities.sao_paulo import sao_paulo
  File "/home/felipe/airflow/dags/cities/sao_paulo.py", line 43, in <module>
    sao_paulo()
  File "/home/felipe/airflow/dags/cities/sao_paulo.py", line 41, in sao_paulo
    raise ValueError('Erro em Sao Paulo!')
ValueError: Erro em Sao Paulo!
[2024-01-09T10:39:55.123-0300] {processor.py:841} WARNING - No viable dags retrieved from /home/felipe/airflow/dags/dag.py
[2024-01-09T10:39:55.160-0300] {processor.py:179} INFO - Processing /home/felipe/airflow/dags/dag.py took 0.326 seconds
[2024-01-09T10:40:31.646-0300] {processor.py:157} INFO - Started process (PID=12025) to work on /home/felipe/airflow/dags/dag.py
[2024-01-09T10:40:31.678-0300] {processor.py:829} INFO - Processing file /home/felipe/airflow/dags/dag.py for tasks to queue
[2024-01-09T10:40:31.678-0300] {logging_mixin.py:154} INFO - [2024-01-09T10:40:31.678-0300] {dagbag.py:536} INFO - Filling up the DagBag from /home/felipe/airflow/dags/dag.py
[2024-01-09T10:40:31.931-0300] {logging_mixin.py:154} INFO - sao_paulo - Error: HTTPConnectionPool(host='api.olhovivo.sptrans.com.br', port=80): Max retries exceeded with url: /v2.1/Login/Autenticar?token=d1bb804b2deb44121c369766969557fac53d34fa4b595f884c13f81ca6de5245 (Caused by NewConnectionError('<urllib3.connection.HTTPConnection object at 0x7f93e05ce7d0>: Failed to establish a new connection: [Errno -3] Temporary failure in name resolution'))
[2024-01-09T10:40:31.933-0300] {logging_mixin.py:154} INFO - [2024-01-09T10:40:31.931-0300] {dagbag.py:346} ERROR - Failed to import: /home/felipe/airflow/dags/dag.py
Traceback (most recent call last):
  File "/home/felipe/.local/lib/python3.11/site-packages/urllib3/connection.py", line 174, in _new_conn
    conn = connection.create_connection(
           ^^^^^^^^^^^^^^^^^^^^^^^^^^^^^
  File "/home/felipe/.local/lib/python3.11/site-packages/urllib3/util/connection.py", line 72, in create_connection
    for res in socket.getaddrinfo(host, port, family, socket.SOCK_STREAM):
               ^^^^^^^^^^^^^^^^^^^^^^^^^^^^^^^^^^^^^^^^^^^^^^^^^^^^^^^^^^
  File "/usr/lib/python3.11/socket.py", line 962, in getaddrinfo
    for res in _socket.getaddrinfo(host, port, family, type, proto, flags):
               ^^^^^^^^^^^^^^^^^^^^^^^^^^^^^^^^^^^^^^^^^^^^^^^^^^^^^^^^^^^
socket.gaierror: [Errno -3] Temporary failure in name resolution

During handling of the above exception, another exception occurred:

Traceback (most recent call last):
  File "/home/felipe/.local/lib/python3.11/site-packages/urllib3/connectionpool.py", line 715, in urlopen
    httplib_response = self._make_request(
                       ^^^^^^^^^^^^^^^^^^^
  File "/home/felipe/.local/lib/python3.11/site-packages/urllib3/connectionpool.py", line 416, in _make_request
    conn.request(method, url, **httplib_request_kw)
  File "/home/felipe/.local/lib/python3.11/site-packages/urllib3/connection.py", line 244, in request
    super(HTTPConnection, self).request(method, url, body=body, headers=headers)
  File "/usr/lib/python3.11/http/client.py", line 1286, in request
    self._send_request(method, url, body, headers, encode_chunked)
  File "/usr/lib/python3.11/http/client.py", line 1332, in _send_request
    self.endheaders(body, encode_chunked=encode_chunked)
  File "/usr/lib/python3.11/http/client.py", line 1281, in endheaders
    self._send_output(message_body, encode_chunked=encode_chunked)
  File "/usr/lib/python3.11/http/client.py", line 1041, in _send_output
    self.send(msg)
  File "/usr/lib/python3.11/http/client.py", line 979, in send
    self.connect()
  File "/home/felipe/.local/lib/python3.11/site-packages/urllib3/connection.py", line 205, in connect
    conn = self._new_conn()
           ^^^^^^^^^^^^^^^^
  File "/home/felipe/.local/lib/python3.11/site-packages/urllib3/connection.py", line 186, in _new_conn
    raise NewConnectionError(
urllib3.exceptions.NewConnectionError: <urllib3.connection.HTTPConnection object at 0x7f93e05ce7d0>: Failed to establish a new connection: [Errno -3] Temporary failure in name resolution

During handling of the above exception, another exception occurred:

Traceback (most recent call last):
  File "/home/felipe/.local/lib/python3.11/site-packages/requests/adapters.py", line 486, in send
    resp = conn.urlopen(
           ^^^^^^^^^^^^^
  File "/home/felipe/.local/lib/python3.11/site-packages/urllib3/connectionpool.py", line 799, in urlopen
    retries = retries.increment(
              ^^^^^^^^^^^^^^^^^^
  File "/home/felipe/.local/lib/python3.11/site-packages/urllib3/util/retry.py", line 592, in increment
    raise MaxRetryError(_pool, url, error or ResponseError(cause))
urllib3.exceptions.MaxRetryError: HTTPConnectionPool(host='api.olhovivo.sptrans.com.br', port=80): Max retries exceeded with url: /v2.1/Login/Autenticar?token=d1bb804b2deb44121c369766969557fac53d34fa4b595f884c13f81ca6de5245 (Caused by NewConnectionError('<urllib3.connection.HTTPConnection object at 0x7f93e05ce7d0>: Failed to establish a new connection: [Errno -3] Temporary failure in name resolution'))

During handling of the above exception, another exception occurred:

Traceback (most recent call last):
  File "/home/felipe/airflow/dags/cities/sao_paulo.py", line 36, in sao_paulo
    response = req()
               ^^^^^
  File "/home/felipe/airflow/dags/cities/sao_paulo.py", line 10, in req
    auth = requests.post(url=(API_URL + "/Login/Autenticar?token=" + TOKEN))
           ^^^^^^^^^^^^^^^^^^^^^^^^^^^^^^^^^^^^^^^^^^^^^^^^^^^^^^^^^^^^^^^^^
  File "/home/felipe/.local/lib/python3.11/site-packages/requests/api.py", line 115, in post
    return request("post", url, data=data, json=json, **kwargs)
           ^^^^^^^^^^^^^^^^^^^^^^^^^^^^^^^^^^^^^^^^^^^^^^^^^^^^
  File "/home/felipe/.local/lib/python3.11/site-packages/requests/api.py", line 59, in request
    return session.request(method=method, url=url, **kwargs)
           ^^^^^^^^^^^^^^^^^^^^^^^^^^^^^^^^^^^^^^^^^^^^^^^^^
  File "/home/felipe/.local/lib/python3.11/site-packages/requests/sessions.py", line 589, in request
    resp = self.send(prep, **send_kwargs)
           ^^^^^^^^^^^^^^^^^^^^^^^^^^^^^^
  File "/home/felipe/.local/lib/python3.11/site-packages/requests/sessions.py", line 703, in send
    r = adapter.send(request, **kwargs)
        ^^^^^^^^^^^^^^^^^^^^^^^^^^^^^^^
  File "/home/felipe/.local/lib/python3.11/site-packages/requests/adapters.py", line 519, in send
    raise ConnectionError(e, request=request)
requests.exceptions.ConnectionError: HTTPConnectionPool(host='api.olhovivo.sptrans.com.br', port=80): Max retries exceeded with url: /v2.1/Login/Autenticar?token=d1bb804b2deb44121c369766969557fac53d34fa4b595f884c13f81ca6de5245 (Caused by NewConnectionError('<urllib3.connection.HTTPConnection object at 0x7f93e05ce7d0>: Failed to establish a new connection: [Errno -3] Temporary failure in name resolution'))

During handling of the above exception, another exception occurred:

Traceback (most recent call last):
  File "/home/felipe/.local/lib/python3.11/site-packages/airflow/models/dagbag.py", line 342, in parse
    loader.exec_module(new_module)
  File "<frozen importlib._bootstrap_external>", line 940, in exec_module
  File "<frozen importlib._bootstrap>", line 241, in _call_with_frames_removed
  File "/home/felipe/airflow/dags/dag.py", line 7, in <module>
    from cities.sao_paulo import sao_paulo
  File "/home/felipe/airflow/dags/cities/sao_paulo.py", line 43, in <module>
    sao_paulo()
  File "/home/felipe/airflow/dags/cities/sao_paulo.py", line 41, in sao_paulo
    raise ValueError('Erro em Sao Paulo!')
ValueError: Erro em Sao Paulo!
[2024-01-09T10:40:31.933-0300] {processor.py:841} WARNING - No viable dags retrieved from /home/felipe/airflow/dags/dag.py
[2024-01-09T10:40:31.971-0300] {processor.py:179} INFO - Processing /home/felipe/airflow/dags/dag.py took 0.327 seconds
[2024-01-09T10:41:06.410-0300] {processor.py:157} INFO - Started process (PID=12187) to work on /home/felipe/airflow/dags/dag.py
[2024-01-09T10:41:06.410-0300] {processor.py:829} INFO - Processing file /home/felipe/airflow/dags/dag.py for tasks to queue
[2024-01-09T10:41:06.411-0300] {logging_mixin.py:154} INFO - [2024-01-09T10:41:06.410-0300] {dagbag.py:536} INFO - Filling up the DagBag from /home/felipe/airflow/dags/dag.py
[2024-01-09T10:41:07.889-0300] {logging_mixin.py:154} INFO - SAVING FILE sp
[2024-01-09T10:41:10.916-0300] {logging_mixin.py:154} INFO - SAVING FILE df
[2024-01-09T10:41:13.380-0300] {logging_mixin.py:154} INFO - SAVING FILE rj
[2024-01-09T10:41:15.002-0300] {logging_mixin.py:154} INFO - SAVING FILE cwb
[2024-01-09T10:41:15.004-0300] {processor.py:839} INFO - DAG(s) dict_keys(['cities']) retrieved from /home/felipe/airflow/dags/dag.py
[2024-01-09T10:41:15.062-0300] {logging_mixin.py:154} INFO - [2024-01-09T10:41:15.062-0300] {dag.py:2941} INFO - Sync 1 DAGs
[2024-01-09T10:41:15.067-0300] {logging_mixin.py:154} INFO - [2024-01-09T10:41:15.067-0300] {dag.py:3722} INFO - Setting next_dagrun for cities to 2024-01-09T13:40:15.067761+00:00, run_after=2024-01-09T13:41:15.067761+00:00
[2024-01-09T10:41:15.076-0300] {processor.py:179} INFO - Processing /home/felipe/airflow/dags/dag.py took 8.669 seconds
[2024-01-09T10:43:07.369-0300] {processor.py:157} INFO - Started process (PID=12443) to work on /home/felipe/airflow/dags/dag.py
[2024-01-09T10:43:07.401-0300] {processor.py:829} INFO - Processing file /home/felipe/airflow/dags/dag.py for tasks to queue
[2024-01-09T10:43:07.402-0300] {logging_mixin.py:154} INFO - [2024-01-09T10:43:07.401-0300] {dagbag.py:536} INFO - Filling up the DagBag from /home/felipe/airflow/dags/dag.py
[2024-01-09T10:43:08.623-0300] {logging_mixin.py:154} INFO - SAVING FILE sp
[2024-01-09T10:43:09.211-0300] {logging_mixin.py:154} INFO - SAVING FILE df
[2024-01-09T10:43:11.304-0300] {logging_mixin.py:154} INFO - SAVING FILE rj
[2024-01-09T10:43:13.109-0300] {logging_mixin.py:154} INFO - SAVING FILE cwb
[2024-01-09T10:43:13.111-0300] {processor.py:839} INFO - DAG(s) dict_keys(['cities']) retrieved from /home/felipe/airflow/dags/dag.py
[2024-01-09T10:43:13.120-0300] {logging_mixin.py:154} INFO - [2024-01-09T10:43:13.120-0300] {dag.py:2941} INFO - Sync 1 DAGs
[2024-01-09T10:43:13.131-0300] {logging_mixin.py:154} INFO - [2024-01-09T10:43:13.131-0300] {dag.py:3722} INFO - Setting next_dagrun for cities to 2024-01-09T13:42:15.067761+00:00, run_after=2024-01-09T13:43:15.067761+00:00
[2024-01-09T10:43:13.174-0300] {processor.py:179} INFO - Processing /home/felipe/airflow/dags/dag.py took 5.808 seconds
[2024-01-09T10:45:12.456-0300] {processor.py:157} INFO - Started process (PID=12699) to work on /home/felipe/airflow/dags/dag.py
[2024-01-09T10:45:12.488-0300] {processor.py:829} INFO - Processing file /home/felipe/airflow/dags/dag.py for tasks to queue
[2024-01-09T10:45:12.489-0300] {logging_mixin.py:154} INFO - [2024-01-09T10:45:12.488-0300] {dagbag.py:536} INFO - Filling up the DagBag from /home/felipe/airflow/dags/dag.py
[2024-01-09T10:45:13.736-0300] {logging_mixin.py:154} INFO - SAVING FILE sp
[2024-01-09T10:45:14.395-0300] {logging_mixin.py:154} INFO - SAVING FILE df
[2024-01-09T10:45:16.762-0300] {logging_mixin.py:154} INFO - SAVING FILE rj
[2024-01-09T10:45:18.337-0300] {logging_mixin.py:154} INFO - SAVING FILE cwb
[2024-01-09T10:45:18.339-0300] {processor.py:839} INFO - DAG(s) dict_keys(['cities']) retrieved from /home/felipe/airflow/dags/dag.py
[2024-01-09T10:45:18.348-0300] {logging_mixin.py:154} INFO - [2024-01-09T10:45:18.348-0300] {dag.py:2941} INFO - Sync 1 DAGs
[2024-01-09T10:45:18.357-0300] {logging_mixin.py:154} INFO - [2024-01-09T10:45:18.357-0300] {dag.py:3722} INFO - Setting next_dagrun for cities to 2024-01-09T13:44:18.357171+00:00, run_after=2024-01-09T13:45:18.357171+00:00
[2024-01-09T10:45:18.367-0300] {processor.py:179} INFO - Processing /home/felipe/airflow/dags/dag.py took 5.913 seconds
[2024-01-09T10:48:06.386-0300] {processor.py:157} INFO - Started process (PID=13550) to work on /home/felipe/airflow/dags/dag.py
[2024-01-09T10:48:06.418-0300] {processor.py:829} INFO - Processing file /home/felipe/airflow/dags/dag.py for tasks to queue
[2024-01-09T10:48:06.418-0300] {logging_mixin.py:154} INFO - [2024-01-09T10:48:06.418-0300] {dagbag.py:536} INFO - Filling up the DagBag from /home/felipe/airflow/dags/dag.py
[2024-01-09T10:48:07.635-0300] {logging_mixin.py:154} INFO - SAVING FILE sp
[2024-01-09T10:48:12.154-0300] {logging_mixin.py:154} INFO - SAVING FILE df
[2024-01-09T10:48:15.516-0300] {logging_mixin.py:154} INFO - SAVING FILE rj
[2024-01-09T10:48:18.684-0300] {logging_mixin.py:154} INFO - SAVING FILE cwb
[2024-01-09T10:48:18.686-0300] {processor.py:839} INFO - DAG(s) dict_keys(['cities']) retrieved from /home/felipe/airflow/dags/dag.py
[2024-01-09T10:48:18.693-0300] {logging_mixin.py:154} INFO - [2024-01-09T10:48:18.693-0300] {dag.py:2941} INFO - Sync 1 DAGs
[2024-01-09T10:48:18.699-0300] {logging_mixin.py:154} INFO - [2024-01-09T10:48:18.699-0300] {dag.py:3722} INFO - Setting next_dagrun for cities to 2024-01-09T13:47:18.699459+00:00, run_after=2024-01-09T13:48:18.699459+00:00
[2024-01-09T10:48:18.741-0300] {processor.py:179} INFO - Processing /home/felipe/airflow/dags/dag.py took 12.357 seconds
[2024-01-09T10:51:06.247-0300] {processor.py:157} INFO - Started process (PID=13913) to work on /home/felipe/airflow/dags/dag.py
[2024-01-09T10:51:06.279-0300] {processor.py:829} INFO - Processing file /home/felipe/airflow/dags/dag.py for tasks to queue
[2024-01-09T10:51:06.279-0300] {logging_mixin.py:154} INFO - [2024-01-09T10:51:06.279-0300] {dagbag.py:536} INFO - Filling up the DagBag from /home/felipe/airflow/dags/dag.py
[2024-01-09T10:51:07.503-0300] {logging_mixin.py:154} INFO - SAVING FILE sp
[2024-01-09T10:51:11.129-0300] {logging_mixin.py:154} INFO - SAVING FILE df
[2024-01-09T10:51:13.474-0300] {logging_mixin.py:154} INFO - SAVING FILE rj
[2024-01-09T10:51:15.110-0300] {logging_mixin.py:154} INFO - SAVING FILE cwb
[2024-01-09T10:51:15.112-0300] {processor.py:839} INFO - DAG(s) dict_keys(['cities']) retrieved from /home/felipe/airflow/dags/dag.py
[2024-01-09T10:51:15.121-0300] {logging_mixin.py:154} INFO - [2024-01-09T10:51:15.121-0300] {dag.py:2941} INFO - Sync 1 DAGs
[2024-01-09T10:51:15.132-0300] {logging_mixin.py:154} INFO - [2024-01-09T10:51:15.132-0300] {dag.py:3722} INFO - Setting next_dagrun for cities to 2024-01-09T13:50:18.699459+00:00, run_after=2024-01-09T13:51:18.699459+00:00
[2024-01-09T10:51:15.177-0300] {processor.py:179} INFO - Processing /home/felipe/airflow/dags/dag.py took 8.932 seconds
[2024-01-09T10:53:13.851-0300] {processor.py:157} INFO - Started process (PID=14165) to work on /home/felipe/airflow/dags/dag.py
[2024-01-09T10:53:13.883-0300] {processor.py:829} INFO - Processing file /home/felipe/airflow/dags/dag.py for tasks to queue
[2024-01-09T10:53:13.883-0300] {logging_mixin.py:154} INFO - [2024-01-09T10:53:13.883-0300] {dagbag.py:536} INFO - Filling up the DagBag from /home/felipe/airflow/dags/dag.py
[2024-01-09T10:53:15.103-0300] {logging_mixin.py:154} INFO - SAVING FILE sp
[2024-01-09T10:53:16.346-0300] {logging_mixin.py:154} INFO - SAVING FILE df
[2024-01-09T10:53:18.653-0300] {logging_mixin.py:154} INFO - SAVING FILE rj
[2024-01-09T10:53:20.333-0300] {logging_mixin.py:154} INFO - SAVING FILE cwb
[2024-01-09T10:53:20.334-0300] {processor.py:839} INFO - DAG(s) dict_keys(['cities']) retrieved from /home/felipe/airflow/dags/dag.py
[2024-01-09T10:53:20.339-0300] {logging_mixin.py:154} INFO - [2024-01-09T10:53:20.339-0300] {dag.py:2941} INFO - Sync 1 DAGs
[2024-01-09T10:53:20.345-0300] {logging_mixin.py:154} INFO - [2024-01-09T10:53:20.345-0300] {dag.py:3722} INFO - Setting next_dagrun for cities to 2024-01-09T13:52:20.345773+00:00, run_after=2024-01-09T13:53:20.345773+00:00
[2024-01-09T10:53:20.385-0300] {processor.py:179} INFO - Processing /home/felipe/airflow/dags/dag.py took 6.537 seconds
[2024-01-09T10:54:07.232-0300] {processor.py:157} INFO - Started process (PID=14445) to work on /home/felipe/airflow/dags/dag.py
[2024-01-09T10:54:07.264-0300] {processor.py:829} INFO - Processing file /home/felipe/airflow/dags/dag.py for tasks to queue
[2024-01-09T10:54:07.264-0300] {logging_mixin.py:154} INFO - [2024-01-09T10:54:07.264-0300] {dagbag.py:536} INFO - Filling up the DagBag from /home/felipe/airflow/dags/dag.py
[2024-01-09T10:54:08.477-0300] {logging_mixin.py:154} INFO - SAVING FILE sp
[2024-01-09T10:54:09.055-0300] {logging_mixin.py:154} INFO - SAVING FILE df
[2024-01-09T10:54:12.049-0300] {logging_mixin.py:154} INFO - SAVING FILE rj
[2024-01-09T10:54:12.835-0300] {logging_mixin.py:154} INFO - SAVING FILE cwb
[2024-01-09T10:54:12.838-0300] {processor.py:839} INFO - DAG(s) dict_keys(['cities']) retrieved from /home/felipe/airflow/dags/dag.py
[2024-01-09T10:54:12.847-0300] {logging_mixin.py:154} INFO - [2024-01-09T10:54:12.846-0300] {dag.py:2941} INFO - Sync 1 DAGs
[2024-01-09T10:54:12.856-0300] {logging_mixin.py:154} INFO - [2024-01-09T10:54:12.856-0300] {dag.py:3722} INFO - Setting next_dagrun for cities to 2024-01-09T13:53:20.345773+00:00, run_after=2024-01-09T13:54:20.345773+00:00
[2024-01-09T10:54:12.898-0300] {processor.py:179} INFO - Processing /home/felipe/airflow/dags/dag.py took 5.668 seconds
[2024-01-09T10:55:10.945-0300] {processor.py:157} INFO - Started process (PID=14705) to work on /home/felipe/airflow/dags/dag.py
[2024-01-09T10:55:10.977-0300] {processor.py:829} INFO - Processing file /home/felipe/airflow/dags/dag.py for tasks to queue
[2024-01-09T10:55:10.978-0300] {logging_mixin.py:154} INFO - [2024-01-09T10:55:10.978-0300] {dagbag.py:536} INFO - Filling up the DagBag from /home/felipe/airflow/dags/dag.py
[2024-01-09T10:55:12.194-0300] {logging_mixin.py:154} INFO - SAVING FILE sp
[2024-01-09T10:55:12.782-0300] {logging_mixin.py:154} INFO - SAVING FILE df
[2024-01-09T10:55:16.105-0300] {logging_mixin.py:154} INFO - SAVING FILE rj
[2024-01-09T10:55:17.852-0300] {logging_mixin.py:154} INFO - SAVING FILE cwb
[2024-01-09T10:55:17.854-0300] {processor.py:839} INFO - DAG(s) dict_keys(['cities']) retrieved from /home/felipe/airflow/dags/dag.py
[2024-01-09T10:55:17.859-0300] {logging_mixin.py:154} INFO - [2024-01-09T10:55:17.859-0300] {dag.py:2941} INFO - Sync 1 DAGs
[2024-01-09T10:55:17.866-0300] {logging_mixin.py:154} INFO - [2024-01-09T10:55:17.865-0300] {dag.py:3722} INFO - Setting next_dagrun for cities to 2024-01-09T13:54:20.345773+00:00, run_after=2024-01-09T13:55:20.345773+00:00
[2024-01-09T10:55:17.931-0300] {processor.py:179} INFO - Processing /home/felipe/airflow/dags/dag.py took 6.988 seconds
[2024-01-09T10:57:17.506-0300] {processor.py:157} INFO - Started process (PID=15073) to work on /home/felipe/airflow/dags/dag.py
[2024-01-09T10:57:17.538-0300] {processor.py:829} INFO - Processing file /home/felipe/airflow/dags/dag.py for tasks to queue
[2024-01-09T10:57:17.538-0300] {logging_mixin.py:154} INFO - [2024-01-09T10:57:17.538-0300] {dagbag.py:536} INFO - Filling up the DagBag from /home/felipe/airflow/dags/dag.py
[2024-01-09T10:57:18.755-0300] {logging_mixin.py:154} INFO - SAVING FILE sp
[2024-01-09T10:57:22.955-0300] {logging_mixin.py:154} INFO - SAVING FILE df
[2024-01-09T10:57:25.300-0300] {logging_mixin.py:154} INFO - SAVING FILE rj
[2024-01-09T10:57:26.101-0300] {logging_mixin.py:154} INFO - SAVING FILE cwb
[2024-01-09T10:57:26.103-0300] {processor.py:839} INFO - DAG(s) dict_keys(['cities']) retrieved from /home/felipe/airflow/dags/dag.py
[2024-01-09T10:57:26.113-0300] {logging_mixin.py:154} INFO - [2024-01-09T10:57:26.112-0300] {dag.py:2941} INFO - Sync 1 DAGs
[2024-01-09T10:57:26.124-0300] {logging_mixin.py:154} INFO - [2024-01-09T10:57:26.124-0300] {dag.py:3722} INFO - Setting next_dagrun for cities to 2024-01-09T13:56:26.124543+00:00, run_after=2024-01-09T13:57:26.124543+00:00
[2024-01-09T10:57:26.169-0300] {processor.py:179} INFO - Processing /home/felipe/airflow/dags/dag.py took 8.665 seconds
[2024-01-09T10:59:14.065-0300] {processor.py:157} INFO - Started process (PID=15343) to work on /home/felipe/airflow/dags/dag.py
[2024-01-09T10:59:14.130-0300] {processor.py:829} INFO - Processing file /home/felipe/airflow/dags/dag.py for tasks to queue
[2024-01-09T10:59:14.130-0300] {logging_mixin.py:154} INFO - [2024-01-09T10:59:14.130-0300] {dagbag.py:536} INFO - Filling up the DagBag from /home/felipe/airflow/dags/dag.py
[2024-01-09T10:59:15.313-0300] {logging_mixin.py:154} INFO - SAVING FILE sp
[2024-01-09T10:59:19.535-0300] {logging_mixin.py:154} INFO - SAVING FILE df
[2024-01-09T10:59:21.874-0300] {logging_mixin.py:154} INFO - SAVING FILE rj
[2024-01-09T10:59:22.652-0300] {logging_mixin.py:154} INFO - SAVING FILE cwb
[2024-01-09T10:59:22.655-0300] {processor.py:839} INFO - DAG(s) dict_keys(['cities']) retrieved from /home/felipe/airflow/dags/dag.py
[2024-01-09T10:59:22.664-0300] {logging_mixin.py:154} INFO - [2024-01-09T10:59:22.664-0300] {dag.py:2941} INFO - Sync 1 DAGs
[2024-01-09T10:59:22.676-0300] {logging_mixin.py:154} INFO - [2024-01-09T10:59:22.676-0300] {dag.py:3722} INFO - Setting next_dagrun for cities to 2024-01-09T13:58:26.124543+00:00, run_after=2024-01-09T13:59:26.124543+00:00
[2024-01-09T10:59:22.720-0300] {processor.py:179} INFO - Processing /home/felipe/airflow/dags/dag.py took 8.657 seconds
[2024-01-09T11:01:53.669-0300] {processor.py:157} INFO - Started process (PID=15767) to work on /home/felipe/airflow/dags/dag.py
[2024-01-09T11:01:53.674-0300] {processor.py:829} INFO - Processing file /home/felipe/airflow/dags/dag.py for tasks to queue
[2024-01-09T11:01:53.675-0300] {logging_mixin.py:154} INFO - [2024-01-09T11:01:53.674-0300] {dagbag.py:536} INFO - Filling up the DagBag from /home/felipe/airflow/dags/dag.py
[2024-01-09T11:01:54.884-0300] {logging_mixin.py:154} INFO - SAVING FILE sp
[2024-01-09T11:01:57.155-0300] {logging_mixin.py:154} INFO - SAVING FILE df
[2024-01-09T11:01:59.965-0300] {logging_mixin.py:154} INFO - SAVING FILE rj
[2024-01-09T11:02:00.784-0300] {logging_mixin.py:154} INFO - SAVING FILE cwb
[2024-01-09T11:02:00.786-0300] {processor.py:839} INFO - DAG(s) dict_keys(['cities']) retrieved from /home/felipe/airflow/dags/dag.py
[2024-01-09T11:02:00.795-0300] {logging_mixin.py:154} INFO - [2024-01-09T11:02:00.795-0300] {dag.py:2941} INFO - Sync 1 DAGs
[2024-01-09T11:02:00.806-0300] {logging_mixin.py:154} INFO - [2024-01-09T11:02:00.806-0300] {dag.py:3722} INFO - Setting next_dagrun for cities to 2024-01-09T14:01:26.124543+00:00, run_after=2024-01-09T14:02:26.124543+00:00
[2024-01-09T11:02:00.851-0300] {processor.py:179} INFO - Processing /home/felipe/airflow/dags/dag.py took 7.184 seconds
[2024-01-09T20:52:38.532-0300] {processor.py:157} INFO - Started process (PID=36037) to work on /home/felipe/airflow/dags/dag.py
[2024-01-09T20:52:38.533-0300] {processor.py:829} INFO - Processing file /home/felipe/airflow/dags/dag.py for tasks to queue
[2024-01-09T20:52:38.533-0300] {logging_mixin.py:154} INFO - [2024-01-09T20:52:38.533-0300] {dagbag.py:536} INFO - Filling up the DagBag from /home/felipe/airflow/dags/dag.py
[2024-01-09T20:52:38.820-0300] {logging_mixin.py:154} INFO - sao_paulo - Error: exceptions must derive from BaseException
[2024-01-09T20:52:38.821-0300] {logging_mixin.py:154} INFO - [2024-01-09T20:52:38.820-0300] {dagbag.py:346} ERROR - Failed to import: /home/felipe/airflow/dags/dag.py
Traceback (most recent call last):
  File "/home/felipe/airflow/dags/cities/sao_paulo.py", line 36, in sao_paulo
    response = req()
               ^^^^^
  File "/home/felipe/airflow/dags/cities/sao_paulo.py", line 12, in req
    raise "Houve um erro na autenticação"
TypeError: exceptions must derive from BaseException

During handling of the above exception, another exception occurred:

Traceback (most recent call last):
  File "/home/felipe/.local/lib/python3.11/site-packages/airflow/models/dagbag.py", line 342, in parse
    loader.exec_module(new_module)
  File "<frozen importlib._bootstrap_external>", line 940, in exec_module
  File "<frozen importlib._bootstrap>", line 241, in _call_with_frames_removed
  File "/home/felipe/airflow/dags/dag.py", line 7, in <module>
    from cities.sao_paulo import sao_paulo
  File "/home/felipe/airflow/dags/cities/sao_paulo.py", line 43, in <module>
    sao_paulo()
  File "/home/felipe/airflow/dags/cities/sao_paulo.py", line 41, in sao_paulo
    raise ValueError('Erro em Sao Paulo!')
ValueError: Erro em Sao Paulo!
[2024-01-09T20:52:38.821-0300] {processor.py:841} WARNING - No viable dags retrieved from /home/felipe/airflow/dags/dag.py
[2024-01-09T20:52:38.904-0300] {processor.py:179} INFO - Processing /home/felipe/airflow/dags/dag.py took 0.374 seconds
[2024-01-09T20:53:28.720-0300] {processor.py:157} INFO - Started process (PID=36490) to work on /home/felipe/airflow/dags/dag.py
[2024-01-09T20:53:28.721-0300] {processor.py:829} INFO - Processing file /home/felipe/airflow/dags/dag.py for tasks to queue
[2024-01-09T20:53:28.722-0300] {logging_mixin.py:154} INFO - [2024-01-09T20:53:28.721-0300] {dagbag.py:536} INFO - Filling up the DagBag from /home/felipe/airflow/dags/dag.py
[2024-01-09T20:53:29.023-0300] {logging_mixin.py:154} INFO - sao_paulo - Error: exceptions must derive from BaseException
[2024-01-09T20:53:29.027-0300] {logging_mixin.py:154} INFO - [2024-01-09T20:53:29.023-0300] {dagbag.py:346} ERROR - Failed to import: /home/felipe/airflow/dags/dag.py
Traceback (most recent call last):
  File "/home/felipe/airflow/dags/cities/sao_paulo.py", line 36, in sao_paulo
    response = req()
               ^^^^^
  File "/home/felipe/airflow/dags/cities/sao_paulo.py", line 12, in req
    raise "Houve um erro na autenticação"
TypeError: exceptions must derive from BaseException

During handling of the above exception, another exception occurred:

Traceback (most recent call last):
  File "/home/felipe/.local/lib/python3.11/site-packages/airflow/models/dagbag.py", line 342, in parse
    loader.exec_module(new_module)
  File "<frozen importlib._bootstrap_external>", line 940, in exec_module
  File "<frozen importlib._bootstrap>", line 241, in _call_with_frames_removed
  File "/home/felipe/airflow/dags/dag.py", line 7, in <module>
    from cities.sao_paulo import sao_paulo
  File "/home/felipe/airflow/dags/cities/sao_paulo.py", line 43, in <module>
    sao_paulo()
  File "/home/felipe/airflow/dags/cities/sao_paulo.py", line 41, in sao_paulo
    raise ValueError('Erro em Sao Paulo!')
ValueError: Erro em Sao Paulo!
[2024-01-09T20:53:29.028-0300] {processor.py:841} WARNING - No viable dags retrieved from /home/felipe/airflow/dags/dag.py
[2024-01-09T20:53:29.037-0300] {processor.py:179} INFO - Processing /home/felipe/airflow/dags/dag.py took 0.319 seconds
[2024-01-09T20:54:07.352-0300] {processor.py:157} INFO - Started process (PID=36605) to work on /home/felipe/airflow/dags/dag.py
[2024-01-09T20:54:07.384-0300] {processor.py:829} INFO - Processing file /home/felipe/airflow/dags/dag.py for tasks to queue
[2024-01-09T20:54:07.385-0300] {logging_mixin.py:154} INFO - [2024-01-09T20:54:07.384-0300] {dagbag.py:536} INFO - Filling up the DagBag from /home/felipe/airflow/dags/dag.py
[2024-01-09T20:54:07.627-0300] {logging_mixin.py:154} INFO - sao_paulo - Error: exceptions must derive from BaseException
[2024-01-09T20:54:07.628-0300] {logging_mixin.py:154} INFO - [2024-01-09T20:54:07.627-0300] {dagbag.py:346} ERROR - Failed to import: /home/felipe/airflow/dags/dag.py
Traceback (most recent call last):
  File "/home/felipe/airflow/dags/cities/sao_paulo.py", line 36, in sao_paulo
    response = req()
               ^^^^^
  File "/home/felipe/airflow/dags/cities/sao_paulo.py", line 12, in req
    raise "Houve um erro na autenticação"
TypeError: exceptions must derive from BaseException

During handling of the above exception, another exception occurred:

Traceback (most recent call last):
  File "/home/felipe/.local/lib/python3.11/site-packages/airflow/models/dagbag.py", line 342, in parse
    loader.exec_module(new_module)
  File "<frozen importlib._bootstrap_external>", line 940, in exec_module
  File "<frozen importlib._bootstrap>", line 241, in _call_with_frames_removed
  File "/home/felipe/airflow/dags/dag.py", line 7, in <module>
    from cities.sao_paulo import sao_paulo
  File "/home/felipe/airflow/dags/cities/sao_paulo.py", line 43, in <module>
    sao_paulo()
  File "/home/felipe/airflow/dags/cities/sao_paulo.py", line 41, in sao_paulo
    raise ValueError('Erro em Sao Paulo!')
ValueError: Erro em Sao Paulo!
[2024-01-09T20:54:07.628-0300] {processor.py:841} WARNING - No viable dags retrieved from /home/felipe/airflow/dags/dag.py
[2024-01-09T20:54:07.668-0300] {processor.py:179} INFO - Processing /home/felipe/airflow/dags/dag.py took 0.318 seconds
[2024-01-09T20:54:40.292-0300] {processor.py:157} INFO - Started process (PID=36681) to work on /home/felipe/airflow/dags/dag.py
[2024-01-09T20:54:40.304-0300] {processor.py:829} INFO - Processing file /home/felipe/airflow/dags/dag.py for tasks to queue
[2024-01-09T20:54:40.305-0300] {logging_mixin.py:154} INFO - [2024-01-09T20:54:40.304-0300] {dagbag.py:536} INFO - Filling up the DagBag from /home/felipe/airflow/dags/dag.py
[2024-01-09T20:54:40.558-0300] {logging_mixin.py:154} INFO - sao_paulo - Error: exceptions must derive from BaseException
[2024-01-09T20:54:40.559-0300] {logging_mixin.py:154} INFO - [2024-01-09T20:54:40.558-0300] {dagbag.py:346} ERROR - Failed to import: /home/felipe/airflow/dags/dag.py
Traceback (most recent call last):
  File "/home/felipe/airflow/dags/cities/sao_paulo.py", line 36, in sao_paulo
    response = req()
               ^^^^^
  File "/home/felipe/airflow/dags/cities/sao_paulo.py", line 12, in req
    raise "Houve um erro na autenticação"
TypeError: exceptions must derive from BaseException

During handling of the above exception, another exception occurred:

Traceback (most recent call last):
  File "/home/felipe/.local/lib/python3.11/site-packages/airflow/models/dagbag.py", line 342, in parse
    loader.exec_module(new_module)
  File "<frozen importlib._bootstrap_external>", line 940, in exec_module
  File "<frozen importlib._bootstrap>", line 241, in _call_with_frames_removed
  File "/home/felipe/airflow/dags/dag.py", line 7, in <module>
    from cities.sao_paulo import sao_paulo
  File "/home/felipe/airflow/dags/cities/sao_paulo.py", line 43, in <module>
    sao_paulo()
  File "/home/felipe/airflow/dags/cities/sao_paulo.py", line 41, in sao_paulo
    raise ValueError('Erro em Sao Paulo!')
ValueError: Erro em Sao Paulo!
[2024-01-09T20:54:40.559-0300] {processor.py:841} WARNING - No viable dags retrieved from /home/felipe/airflow/dags/dag.py
[2024-01-09T20:54:40.598-0300] {processor.py:179} INFO - Processing /home/felipe/airflow/dags/dag.py took 0.309 seconds
[2024-01-09T20:55:16.707-0300] {processor.py:157} INFO - Started process (PID=36775) to work on /home/felipe/airflow/dags/dag.py
[2024-01-09T20:55:16.739-0300] {processor.py:829} INFO - Processing file /home/felipe/airflow/dags/dag.py for tasks to queue
[2024-01-09T20:55:16.740-0300] {logging_mixin.py:154} INFO - [2024-01-09T20:55:16.739-0300] {dagbag.py:536} INFO - Filling up the DagBag from /home/felipe/airflow/dags/dag.py
[2024-01-09T20:55:16.995-0300] {logging_mixin.py:154} INFO - sao_paulo - Error: exceptions must derive from BaseException
[2024-01-09T20:55:16.996-0300] {logging_mixin.py:154} INFO - [2024-01-09T20:55:16.995-0300] {dagbag.py:346} ERROR - Failed to import: /home/felipe/airflow/dags/dag.py
Traceback (most recent call last):
  File "/home/felipe/airflow/dags/cities/sao_paulo.py", line 36, in sao_paulo
    response = req()
               ^^^^^
  File "/home/felipe/airflow/dags/cities/sao_paulo.py", line 12, in req
    raise "Houve um erro na autenticação"
TypeError: exceptions must derive from BaseException

During handling of the above exception, another exception occurred:

Traceback (most recent call last):
  File "/home/felipe/.local/lib/python3.11/site-packages/airflow/models/dagbag.py", line 342, in parse
    loader.exec_module(new_module)
  File "<frozen importlib._bootstrap_external>", line 940, in exec_module
  File "<frozen importlib._bootstrap>", line 241, in _call_with_frames_removed
  File "/home/felipe/airflow/dags/dag.py", line 7, in <module>
    from cities.sao_paulo import sao_paulo
  File "/home/felipe/airflow/dags/cities/sao_paulo.py", line 43, in <module>
    sao_paulo()
  File "/home/felipe/airflow/dags/cities/sao_paulo.py", line 41, in sao_paulo
    raise ValueError('Erro em Sao Paulo!')
ValueError: Erro em Sao Paulo!
[2024-01-09T20:55:16.996-0300] {processor.py:841} WARNING - No viable dags retrieved from /home/felipe/airflow/dags/dag.py
[2024-01-09T20:55:17.151-0300] {processor.py:179} INFO - Processing /home/felipe/airflow/dags/dag.py took 0.446 seconds
[2024-01-09T20:55:53.070-0300] {processor.py:157} INFO - Started process (PID=36865) to work on /home/felipe/airflow/dags/dag.py
[2024-01-09T20:55:53.102-0300] {processor.py:829} INFO - Processing file /home/felipe/airflow/dags/dag.py for tasks to queue
[2024-01-09T20:55:53.103-0300] {logging_mixin.py:154} INFO - [2024-01-09T20:55:53.103-0300] {dagbag.py:536} INFO - Filling up the DagBag from /home/felipe/airflow/dags/dag.py
[2024-01-09T20:55:53.468-0300] {logging_mixin.py:154} INFO - sao_paulo - Error: exceptions must derive from BaseException
[2024-01-09T20:55:53.470-0300] {logging_mixin.py:154} INFO - [2024-01-09T20:55:53.469-0300] {dagbag.py:346} ERROR - Failed to import: /home/felipe/airflow/dags/dag.py
Traceback (most recent call last):
  File "/home/felipe/airflow/dags/cities/sao_paulo.py", line 36, in sao_paulo
    response = req()
               ^^^^^
  File "/home/felipe/airflow/dags/cities/sao_paulo.py", line 12, in req
    raise "Houve um erro na autenticação"
TypeError: exceptions must derive from BaseException

During handling of the above exception, another exception occurred:

Traceback (most recent call last):
  File "/home/felipe/.local/lib/python3.11/site-packages/airflow/models/dagbag.py", line 342, in parse
    loader.exec_module(new_module)
  File "<frozen importlib._bootstrap_external>", line 940, in exec_module
  File "<frozen importlib._bootstrap>", line 241, in _call_with_frames_removed
  File "/home/felipe/airflow/dags/dag.py", line 7, in <module>
    from cities.sao_paulo import sao_paulo
  File "/home/felipe/airflow/dags/cities/sao_paulo.py", line 43, in <module>
    sao_paulo()
  File "/home/felipe/airflow/dags/cities/sao_paulo.py", line 41, in sao_paulo
    raise ValueError('Erro em Sao Paulo!')
ValueError: Erro em Sao Paulo!
[2024-01-09T20:55:53.470-0300] {processor.py:841} WARNING - No viable dags retrieved from /home/felipe/airflow/dags/dag.py
[2024-01-09T20:55:53.509-0300] {processor.py:179} INFO - Processing /home/felipe/airflow/dags/dag.py took 0.441 seconds
[2024-01-09T20:56:29.236-0300] {processor.py:157} INFO - Started process (PID=36944) to work on /home/felipe/airflow/dags/dag.py
[2024-01-09T20:56:29.268-0300] {processor.py:829} INFO - Processing file /home/felipe/airflow/dags/dag.py for tasks to queue
[2024-01-09T20:56:29.269-0300] {logging_mixin.py:154} INFO - [2024-01-09T20:56:29.269-0300] {dagbag.py:536} INFO - Filling up the DagBag from /home/felipe/airflow/dags/dag.py
[2024-01-09T20:56:29.528-0300] {logging_mixin.py:154} INFO - sao_paulo - Error: exceptions must derive from BaseException
[2024-01-09T20:56:29.528-0300] {logging_mixin.py:154} INFO - [2024-01-09T20:56:29.528-0300] {dagbag.py:346} ERROR - Failed to import: /home/felipe/airflow/dags/dag.py
Traceback (most recent call last):
  File "/home/felipe/airflow/dags/cities/sao_paulo.py", line 36, in sao_paulo
    response = req()
               ^^^^^
  File "/home/felipe/airflow/dags/cities/sao_paulo.py", line 12, in req
    raise "Houve um erro na autenticação"
TypeError: exceptions must derive from BaseException

During handling of the above exception, another exception occurred:

Traceback (most recent call last):
  File "/home/felipe/.local/lib/python3.11/site-packages/airflow/models/dagbag.py", line 342, in parse
    loader.exec_module(new_module)
  File "<frozen importlib._bootstrap_external>", line 940, in exec_module
  File "<frozen importlib._bootstrap>", line 241, in _call_with_frames_removed
  File "/home/felipe/airflow/dags/dag.py", line 7, in <module>
    from cities.sao_paulo import sao_paulo
  File "/home/felipe/airflow/dags/cities/sao_paulo.py", line 43, in <module>
    sao_paulo()
  File "/home/felipe/airflow/dags/cities/sao_paulo.py", line 41, in sao_paulo
    raise ValueError('Erro em Sao Paulo!')
ValueError: Erro em Sao Paulo!
[2024-01-09T20:56:29.529-0300] {processor.py:841} WARNING - No viable dags retrieved from /home/felipe/airflow/dags/dag.py
[2024-01-09T20:56:29.569-0300] {processor.py:179} INFO - Processing /home/felipe/airflow/dags/dag.py took 0.335 seconds
[2024-01-09T20:57:03.442-0300] {processor.py:157} INFO - Started process (PID=37023) to work on /home/felipe/airflow/dags/dag.py
[2024-01-09T20:57:03.474-0300] {processor.py:829} INFO - Processing file /home/felipe/airflow/dags/dag.py for tasks to queue
[2024-01-09T20:57:03.475-0300] {logging_mixin.py:154} INFO - [2024-01-09T20:57:03.474-0300] {dagbag.py:536} INFO - Filling up the DagBag from /home/felipe/airflow/dags/dag.py
[2024-01-09T20:57:03.839-0300] {logging_mixin.py:154} INFO - sao_paulo - Error: exceptions must derive from BaseException
[2024-01-09T20:57:03.840-0300] {logging_mixin.py:154} INFO - [2024-01-09T20:57:03.839-0300] {dagbag.py:346} ERROR - Failed to import: /home/felipe/airflow/dags/dag.py
Traceback (most recent call last):
  File "/home/felipe/airflow/dags/cities/sao_paulo.py", line 36, in sao_paulo
    response = req()
               ^^^^^
  File "/home/felipe/airflow/dags/cities/sao_paulo.py", line 12, in req
    raise "Houve um erro na autenticação"
TypeError: exceptions must derive from BaseException

During handling of the above exception, another exception occurred:

Traceback (most recent call last):
  File "/home/felipe/.local/lib/python3.11/site-packages/airflow/models/dagbag.py", line 342, in parse
    loader.exec_module(new_module)
  File "<frozen importlib._bootstrap_external>", line 940, in exec_module
  File "<frozen importlib._bootstrap>", line 241, in _call_with_frames_removed
  File "/home/felipe/airflow/dags/dag.py", line 7, in <module>
    from cities.sao_paulo import sao_paulo
  File "/home/felipe/airflow/dags/cities/sao_paulo.py", line 43, in <module>
    sao_paulo()
  File "/home/felipe/airflow/dags/cities/sao_paulo.py", line 41, in sao_paulo
    raise ValueError('Erro em Sao Paulo!')
ValueError: Erro em Sao Paulo!
[2024-01-09T20:57:03.841-0300] {processor.py:841} WARNING - No viable dags retrieved from /home/felipe/airflow/dags/dag.py
[2024-01-09T20:57:03.879-0300] {processor.py:179} INFO - Processing /home/felipe/airflow/dags/dag.py took 0.440 seconds
[2024-01-09T20:57:36.449-0300] {processor.py:157} INFO - Started process (PID=37107) to work on /home/felipe/airflow/dags/dag.py
[2024-01-09T20:57:36.481-0300] {processor.py:829} INFO - Processing file /home/felipe/airflow/dags/dag.py for tasks to queue
[2024-01-09T20:57:36.481-0300] {logging_mixin.py:154} INFO - [2024-01-09T20:57:36.481-0300] {dagbag.py:536} INFO - Filling up the DagBag from /home/felipe/airflow/dags/dag.py
[2024-01-09T20:57:36.835-0300] {logging_mixin.py:154} INFO - sao_paulo - Error: exceptions must derive from BaseException
[2024-01-09T20:57:36.836-0300] {logging_mixin.py:154} INFO - [2024-01-09T20:57:36.835-0300] {dagbag.py:346} ERROR - Failed to import: /home/felipe/airflow/dags/dag.py
Traceback (most recent call last):
  File "/home/felipe/airflow/dags/cities/sao_paulo.py", line 36, in sao_paulo
    response = req()
               ^^^^^
  File "/home/felipe/airflow/dags/cities/sao_paulo.py", line 12, in req
    raise "Houve um erro na autenticação"
TypeError: exceptions must derive from BaseException

During handling of the above exception, another exception occurred:

Traceback (most recent call last):
  File "/home/felipe/.local/lib/python3.11/site-packages/airflow/models/dagbag.py", line 342, in parse
    loader.exec_module(new_module)
  File "<frozen importlib._bootstrap_external>", line 940, in exec_module
  File "<frozen importlib._bootstrap>", line 241, in _call_with_frames_removed
  File "/home/felipe/airflow/dags/dag.py", line 7, in <module>
    from cities.sao_paulo import sao_paulo
  File "/home/felipe/airflow/dags/cities/sao_paulo.py", line 43, in <module>
    sao_paulo()
  File "/home/felipe/airflow/dags/cities/sao_paulo.py", line 41, in sao_paulo
    raise ValueError('Erro em Sao Paulo!')
ValueError: Erro em Sao Paulo!
[2024-01-09T20:57:36.836-0300] {processor.py:841} WARNING - No viable dags retrieved from /home/felipe/airflow/dags/dag.py
[2024-01-09T20:57:36.874-0300] {processor.py:179} INFO - Processing /home/felipe/airflow/dags/dag.py took 0.427 seconds
[2024-01-09T20:58:09.213-0300] {processor.py:157} INFO - Started process (PID=37186) to work on /home/felipe/airflow/dags/dag.py
[2024-01-09T20:58:09.245-0300] {processor.py:829} INFO - Processing file /home/felipe/airflow/dags/dag.py for tasks to queue
[2024-01-09T20:58:09.246-0300] {logging_mixin.py:154} INFO - [2024-01-09T20:58:09.246-0300] {dagbag.py:536} INFO - Filling up the DagBag from /home/felipe/airflow/dags/dag.py
[2024-01-09T20:58:09.496-0300] {logging_mixin.py:154} INFO - sao_paulo - Error: exceptions must derive from BaseException
[2024-01-09T20:58:09.497-0300] {logging_mixin.py:154} INFO - [2024-01-09T20:58:09.496-0300] {dagbag.py:346} ERROR - Failed to import: /home/felipe/airflow/dags/dag.py
Traceback (most recent call last):
  File "/home/felipe/airflow/dags/cities/sao_paulo.py", line 36, in sao_paulo
    response = req()
               ^^^^^
  File "/home/felipe/airflow/dags/cities/sao_paulo.py", line 12, in req
    raise "Houve um erro na autenticação"
TypeError: exceptions must derive from BaseException

During handling of the above exception, another exception occurred:

Traceback (most recent call last):
  File "/home/felipe/.local/lib/python3.11/site-packages/airflow/models/dagbag.py", line 342, in parse
    loader.exec_module(new_module)
  File "<frozen importlib._bootstrap_external>", line 940, in exec_module
  File "<frozen importlib._bootstrap>", line 241, in _call_with_frames_removed
  File "/home/felipe/airflow/dags/dag.py", line 7, in <module>
    from cities.sao_paulo import sao_paulo
  File "/home/felipe/airflow/dags/cities/sao_paulo.py", line 43, in <module>
    sao_paulo()
  File "/home/felipe/airflow/dags/cities/sao_paulo.py", line 41, in sao_paulo
    raise ValueError('Erro em Sao Paulo!')
ValueError: Erro em Sao Paulo!
[2024-01-09T20:58:09.497-0300] {processor.py:841} WARNING - No viable dags retrieved from /home/felipe/airflow/dags/dag.py
[2024-01-09T20:58:09.538-0300] {processor.py:179} INFO - Processing /home/felipe/airflow/dags/dag.py took 0.327 seconds
[2024-01-09T20:58:45.498-0300] {processor.py:157} INFO - Started process (PID=37261) to work on /home/felipe/airflow/dags/dag.py
[2024-01-09T20:58:45.530-0300] {processor.py:829} INFO - Processing file /home/felipe/airflow/dags/dag.py for tasks to queue
[2024-01-09T20:58:45.530-0300] {logging_mixin.py:154} INFO - [2024-01-09T20:58:45.530-0300] {dagbag.py:536} INFO - Filling up the DagBag from /home/felipe/airflow/dags/dag.py
[2024-01-09T20:58:45.883-0300] {logging_mixin.py:154} INFO - sao_paulo - Error: exceptions must derive from BaseException
[2024-01-09T20:58:45.884-0300] {logging_mixin.py:154} INFO - [2024-01-09T20:58:45.883-0300] {dagbag.py:346} ERROR - Failed to import: /home/felipe/airflow/dags/dag.py
Traceback (most recent call last):
  File "/home/felipe/airflow/dags/cities/sao_paulo.py", line 36, in sao_paulo
    response = req()
               ^^^^^
  File "/home/felipe/airflow/dags/cities/sao_paulo.py", line 12, in req
    raise "Houve um erro na autenticação"
TypeError: exceptions must derive from BaseException

During handling of the above exception, another exception occurred:

Traceback (most recent call last):
  File "/home/felipe/.local/lib/python3.11/site-packages/airflow/models/dagbag.py", line 342, in parse
    loader.exec_module(new_module)
  File "<frozen importlib._bootstrap_external>", line 940, in exec_module
  File "<frozen importlib._bootstrap>", line 241, in _call_with_frames_removed
  File "/home/felipe/airflow/dags/dag.py", line 7, in <module>
    from cities.sao_paulo import sao_paulo
  File "/home/felipe/airflow/dags/cities/sao_paulo.py", line 43, in <module>
    sao_paulo()
  File "/home/felipe/airflow/dags/cities/sao_paulo.py", line 41, in sao_paulo
    raise ValueError('Erro em Sao Paulo!')
ValueError: Erro em Sao Paulo!
[2024-01-09T20:58:45.884-0300] {processor.py:841} WARNING - No viable dags retrieved from /home/felipe/airflow/dags/dag.py
[2024-01-09T20:58:45.922-0300] {processor.py:179} INFO - Processing /home/felipe/airflow/dags/dag.py took 0.426 seconds
[2024-01-09T20:59:20.041-0300] {processor.py:157} INFO - Started process (PID=37359) to work on /home/felipe/airflow/dags/dag.py
[2024-01-09T20:59:20.073-0300] {processor.py:829} INFO - Processing file /home/felipe/airflow/dags/dag.py for tasks to queue
[2024-01-09T20:59:20.074-0300] {logging_mixin.py:154} INFO - [2024-01-09T20:59:20.074-0300] {dagbag.py:536} INFO - Filling up the DagBag from /home/felipe/airflow/dags/dag.py
[2024-01-09T20:59:20.430-0300] {logging_mixin.py:154} INFO - sao_paulo - Error: exceptions must derive from BaseException
[2024-01-09T20:59:20.431-0300] {logging_mixin.py:154} INFO - [2024-01-09T20:59:20.430-0300] {dagbag.py:346} ERROR - Failed to import: /home/felipe/airflow/dags/dag.py
Traceback (most recent call last):
  File "/home/felipe/airflow/dags/cities/sao_paulo.py", line 36, in sao_paulo
    response = req()
               ^^^^^
  File "/home/felipe/airflow/dags/cities/sao_paulo.py", line 12, in req
    raise "Houve um erro na autenticação"
TypeError: exceptions must derive from BaseException

During handling of the above exception, another exception occurred:

Traceback (most recent call last):
  File "/home/felipe/.local/lib/python3.11/site-packages/airflow/models/dagbag.py", line 342, in parse
    loader.exec_module(new_module)
  File "<frozen importlib._bootstrap_external>", line 940, in exec_module
  File "<frozen importlib._bootstrap>", line 241, in _call_with_frames_removed
  File "/home/felipe/airflow/dags/dag.py", line 7, in <module>
    from cities.sao_paulo import sao_paulo
  File "/home/felipe/airflow/dags/cities/sao_paulo.py", line 43, in <module>
    sao_paulo()
  File "/home/felipe/airflow/dags/cities/sao_paulo.py", line 41, in sao_paulo
    raise ValueError('Erro em Sao Paulo!')
ValueError: Erro em Sao Paulo!
[2024-01-09T20:59:20.432-0300] {processor.py:841} WARNING - No viable dags retrieved from /home/felipe/airflow/dags/dag.py
[2024-01-09T20:59:20.472-0300] {processor.py:179} INFO - Processing /home/felipe/airflow/dags/dag.py took 0.434 seconds
[2024-01-09T20:59:57.412-0300] {processor.py:157} INFO - Started process (PID=37437) to work on /home/felipe/airflow/dags/dag.py
[2024-01-09T20:59:57.444-0300] {processor.py:829} INFO - Processing file /home/felipe/airflow/dags/dag.py for tasks to queue
[2024-01-09T20:59:57.444-0300] {logging_mixin.py:154} INFO - [2024-01-09T20:59:57.444-0300] {dagbag.py:536} INFO - Filling up the DagBag from /home/felipe/airflow/dags/dag.py
[2024-01-09T21:00:02.889-0300] {logging_mixin.py:154} INFO - sao_paulo - Error: exceptions must derive from BaseException
[2024-01-09T21:00:02.890-0300] {logging_mixin.py:154} INFO - [2024-01-09T21:00:02.889-0300] {dagbag.py:346} ERROR - Failed to import: /home/felipe/airflow/dags/dag.py
Traceback (most recent call last):
  File "/home/felipe/airflow/dags/cities/sao_paulo.py", line 36, in sao_paulo
    response = req()
               ^^^^^
  File "/home/felipe/airflow/dags/cities/sao_paulo.py", line 12, in req
    raise "Houve um erro na autenticação"
TypeError: exceptions must derive from BaseException

During handling of the above exception, another exception occurred:

Traceback (most recent call last):
  File "/home/felipe/.local/lib/python3.11/site-packages/airflow/models/dagbag.py", line 342, in parse
    loader.exec_module(new_module)
  File "<frozen importlib._bootstrap_external>", line 940, in exec_module
  File "<frozen importlib._bootstrap>", line 241, in _call_with_frames_removed
  File "/home/felipe/airflow/dags/dag.py", line 7, in <module>
    from cities.sao_paulo import sao_paulo
  File "/home/felipe/airflow/dags/cities/sao_paulo.py", line 43, in <module>
    sao_paulo()
  File "/home/felipe/airflow/dags/cities/sao_paulo.py", line 41, in sao_paulo
    raise ValueError('Erro em Sao Paulo!')
ValueError: Erro em Sao Paulo!
[2024-01-09T21:00:02.890-0300] {processor.py:841} WARNING - No viable dags retrieved from /home/felipe/airflow/dags/dag.py
[2024-01-09T21:00:02.928-0300] {processor.py:179} INFO - Processing /home/felipe/airflow/dags/dag.py took 5.518 seconds
